Workbook

Sheet SEGUIMIENTO_PROYECTOS
A1: CONTROL DE PROYECTOS — ENTREGABLES Y CONFORMIDAD DEL SERVICIO
A2: Actualizado al: 29/05/2026 · VERDE=OK ROJO=PENDIENTE AMARILLO=Falta firma AZUL=En proceso GRIS=No aplica
A3: DATOS DEL PROYECTO | E3: GESTIÓN | H3: RESPONSABLES | J3: ENTREGABLES SIG | T3: COMENTARIOS | U3: ÚLT. SEGUIMIENTO | V3: % SIG | W3: ESTADO
A4: AÑO CIERRE | B4: N° PROYECTO | C4: NOMBRE DEL PROYECTO | D4: TIPO SGC | E4: ALCANCE DEL SERVICIO | F4: ETAPA ACTUAL | G4: FECHA CIERRE SERVICIO | H4: RESPONSABLE (JEFE) | I4: EQUIPO / JS (referencial) | J4: FICHA PROY. | K4: ACS | L4: SERVIDOR SIG | M4: EVAL. PROV. CCP | N4: DESEMPEÑO PROV. | O4: LECCIONES APRENDIDAS | P4: REPORTES (RA) | Q4: ACTAS REUNIÓN | R4: ESC / SOLICITUD CLIENTE | S4: DEBIDA DILIGENCIA | T4: COMENTARIOS | U4: ÚLT. SEGUIMIENTO | V4: % CUMPL. SIG | W4: ESTADO GENERAL | X4: APLICA (aux) | Y4: PTS (aux)
X5: =10-COUNTIF(J5:S5,"NO APLICA")-COUNTIF(J5:S5,"-")-COUNTIF(J5:S5,"") -> 0 | Y5: =COUNTIF(J5:S5,"OK")+COUNTIF(J5:S5,"EN PROCESO")*0.5 -> 0
A6: 2026 | B6: 23004 | C6: OBRAS INTERBANK | D6: D | E6: SUP | F6: POR INICIAR | H6: B. López | O6: NO APLICA | Q6: NO APLICA | S6: NO APLICA | T6: Inicio 08-06 | V6: =IFERROR((COUNTIF(J6:S6,"OK")+COUNTIF(J6:S6,"EN PROCESO")*0.5)/(10-COUNTIF(J6:S6,"NO APLICA")-COUNTIF(J6:S6,"DESCARTADA")-COUNTIF(J6:S6,"-")-COUNTIF(J6:S6,"")),"") | W6: =IF(ISNUMBER(V6),IF(V6>=0.9,"CONFORME",IF(V6>=0.5,"ALERTA","CRITICO")),IF(F6="CANCELADO","CANCELADO",IF(F6="STAND BY","STAND BY",IF(F6="DESCARTADO","DESCARTADO","S/D")))) -> S/D | X6: =10-COUNTIF(J6:S6,"NO APLICA")-COUNTIF(J6:S6,"-")-COUNTIF(J6:S6,"") -> 0 | Y6: =COUNTIF(J6:S6,"OK")+COUNTIF(J6:S6,"EN PROCESO")*0.5 -> 0
A7: 2026 | B7: 23003 | C7: ASCENSOR BCP HUANCAYO | D7: D | E7: SUP | F7: SUP | G7: 46189 | H7: F. Choque | I7: Nataly Muñante | J7: NO APLICA | L7: PENDIENTE | M7: NO APLICA | N7: NO APLICA | O7: NO APLICA | P7: OK | Q7: NO APLICA | S7: NO APLICA | V7: =IFERROR((COUNTIF(J7:S7,"OK")+COUNTIF(J7:S7,"EN PROCESO")*0.5)/(10-COUNTIF(J7:S7,"NO APLICA")-COUNTIF(J7:S7,"DESCARTADA")-COUNTIF(J7:S7,"-")-COUNTIF(J7:S7,"")),"") -> 0.5 | W7: =IF(ISNUMBER(V7),IF(V7>=0.9,"CONFORME",IF(V7>=0.5,"ALERTA","CRITICO")),IF(F7="CANCELADO","CANCELADO",IF(F7="STAND BY","STAND BY",IF(F7="DESCARTADO","DESCARTADO","S/D")))) -> ALERTA | X7: =10-COUNTIF(J7:S7,"NO APLICA")-COUNTIF(J7:S7,"-")-COUNTIF(J7:S7,"") -> 2 | Y7: =COUNTIF(J7:S7,"OK")+COUNTIF(J7:S7,"EN PROCESO")*0.5 -> 1
A8: 2026 | B8: 23002 | C8: SODIMAC SAN MIGUEL | D8: D | E8: SUP | F8: SUP | G8: 46203 | H8: B. López | J8: NO APLICA | K8: NO APLICA | M8: NO APLICA | N8: NO APLICA | O8: NO APLICA | P8: NO APLICA | Q8: NO APLICA | S8: NO APLICA | V8: =IFERROR((COUNTIF(J8:S8,"OK")+COUNTIF(J8:S8,"EN PROCESO")*0.5)/(10-COUNTIF(J8:S8,"NO APLICA")-COUNTIF(J8:S8,"DESCARTADA")-COUNTIF(J8:S8,"-")-COUNTIF(J8:S8,"")),"") | W8: =IF(ISNUMBER(V8),IF(V8>=0.9,"CONFORME",IF(V8>=0.5,"ALERTA","CRITICO")),IF(F8="CANCELADO","CANCELADO",IF(F8="STAND BY","STAND BY",IF(F8="DESCARTADO","DESCARTADO","S/D")))) -> S/D | X8: =10-COUNTIF(J8:S8,"NO APLICA")-COUNTIF(J8:S8,"-")-COUNTIF(J8:S8,"") -> 0 | Y8: =COUNTIF(J8:S8,"OK")+COUNTIF(J8:S8,"EN PROCESO")*0.5 -> 0
A9: 2026 | B9: 23001 | C9: AUDITORÍA HAYDUK | D9: D | E9: CONS | F9: POR INICIAR | H9: P. Lavado | J9: NO APLICA | O9: NO APLICA | Q9: NO APLICA | V9: =IFERROR((COUNTIF(J9:S9,"OK")+COUNTIF(J9:S9,"EN PROCESO")*0.5)/(10-COUNTIF(J9:S9,"NO APLICA")-COUNTIF(J9:S9,"DESCARTADA")-COUNTIF(J9:S9,"-")-COUNTIF(J9:S9,"")),"") | W9: =IF(ISNUMBER(V9),IF(V9>=0.9,"CONFORME",IF(V9>=0.5,"ALERTA","CRITICO")),IF(F9="CANCELADO","CANCELADO",IF(F9="STAND BY","STAND BY",IF(F9="DESCARTADO","DESCARTADO","S/D")))) -> S/D | X9: =10-COUNTIF(J9:S9,"NO APLICA")-COUNTIF(J9:S9,"-")-COUNTIF(J9:S9,"") -> 0 | Y9: =COUNTIF(J9:S9,"OK")+COUNTIF(J9:S9,"EN PROCESO")*0.5 -> 0
A10: 2026 | B10: 23000 | C10: AMPLIACIÓN CD FF&VV CENCOSUD | D10: A | E10: ING, LIC, SUP | F10: ING | H10: M. Becerra | J10: PENDIENTE | V10: =IFERROR((COUNTIF(J10:S10,"OK")+COUNTIF(J10:S10,"EN PROCESO")*0.5)/(10-COUNTIF(J10:S10,"NO APLICA")-COUNTIF(J10:S10,"DESCARTADA")-COUNTIF(J10:S10,"-")-COUNTIF(J10:S10,"")),"") -> 0 | W10: =IF(ISNUMBER(V10),IF(V10>=0.9,"CONFORME",IF(V10>=0.5,"ALERTA","CRITICO")),IF(F10="CANCELADO","CANCELADO",IF(F10="STAND BY","STAND BY",IF(F10="DESCARTADO","DESCARTADO","S/D")))) -> CRITICO | X10: =10-COUNTIF(J10:S10,"NO APLICA")-COUNTIF(J10:S10,"-")-COUNTIF(J10:S10,"") -> 1 | Y10: =COUNTIF(J10:S10,"OK")+COUNTIF(J10:S10,"EN PROCESO")*0.5 -> 0
A11: 2026 | B11: 22999 | C11: ESCALERA PISO 7 y 8 OFICINAS TMH | D11: D | E11: SUP | F11: SUP | G11: 46193 | H11: F. Choque | I11: José Cruz | J11: NO APLICA | L11: PENDIENTE | M11: NO APLICA | N11: NO APLICA | O11: NO APLICA | P11: OK | Q11: OK | S11: NO APLICA | V11: =IFERROR((COUNTIF(J11:S11,"OK")+COUNTIF(J11:S11,"EN PROCESO")*0.5)/(10-COUNTIF(J11:S11,"NO APLICA")-COUNTIF(J11:S11,"DESCARTADA")-COUNTIF(J11:S11,"-")-COUNTIF(J11:S11,"")),"") -> 0.66666667 | W11: =IF(ISNUMBER(V11),IF(V11>=0.9,"CONFORME",IF(V11>=0.5,"ALERTA","CRITICO")),IF(F11="CANCELADO","CANCELADO",IF(F11="STAND BY","STAND BY",IF(F11="DESCARTADO","DESCARTADO","S/D")))) -> ALERTA | X11: =10-COUNTIF(J11:S11,"NO APLICA")-COUNTIF(J11:S11,"-")-COUNTIF(J11:S11,"") -> 3 | Y11: =COUNTIF(J11:S11,"OK")+COUNTIF(J11:S11,"EN PROCESO")*0.5 -> 2
A12: 2026 | B12: 22998 | C12: MÓDULOS PUKAMANI MAXCO | D12: D | E12: ING | F12: ING | G12: 46188 | H12: M. Becerra | J12: NO APLICA | L12: PENDIENTE | M12: PENDIENTE | O12: NO APLICA | P12: NO APLICA | Q12: NO APLICA | S12: EN PROCESO | V12: =IFERROR((COUNTIF(J12:S12,"OK")+COUNTIF(J12:S12,"EN PROCESO")*0.5)/(10-COUNTIF(J12:S12,"NO APLICA")-COUNTIF(J12:S12,"DESCARTADA")-COUNTIF(J12:S12,"-")-COUNTIF(J12:S12,"")),"") -> 0.16666667 | W12: =IF(ISNUMBER(V12),IF(V12>=0.9,"CONFORME",IF(V12>=0.5,"ALERTA","CRITICO")),IF(F12="CANCELADO","CANCELADO",IF(F12="STAND BY","STAND BY",IF(F12="DESCARTADO","DESCARTADO","S/D")))) -> CRITICO | X12: =10-COUNTIF(J12:S12,"NO APLICA")-COUNTIF(J12:S12,"-")-COUNTIF(J12:S12,"") -> 3 | Y12: =COUNTIF(J12:S12,"OK")+COUNTIF(J12:S12,"EN PROCESO")*0.5 -> 0.5
A13: 2026 | B13: 22997 | C13: H.U. VELAMAR ETAPAS 2 Y 3 PISCO | D13: C | E13: SUP | F13: SUP | G13: 46260 | H13: B. López | I13: Augusto Quio | J13: PENDIENTE | L13: PENDIENTE | M13: NO APLICA | P13: OK | Q13: PENDIENTE | S13: NO APLICA | V13: =IFERROR((COUNTIF(J13:S13,"OK")+COUNTIF(J13:S13,"EN PROCESO")*0.5)/(10-COUNTIF(J13:S13,"NO APLICA")-COUNTIF(J13:S13,"DESCARTADA")-COUNTIF(J13:S13,"-")-COUNTIF(J13:S13,"")),"") -> 0.25 | W13: =IF(ISNUMBER(V13),IF(V13>=0.9,"CONFORME",IF(V13>=0.5,"ALERTA","CRITICO")),IF(F13="CANCELADO","CANCELADO",IF(F13="STAND BY","STAND BY",IF(F13="DESCARTADO","DESCARTADO","S/D")))) -> CRITICO | X13: =10-COUNTIF(J13:S13,"NO APLICA")-COUNTIF(J13:S13,"-")-COUNTIF(J13:S13,"") -> 4 | Y13: =COUNTIF(J13:S13,"OK")+COUNTIF(J13:S13,"EN PROCESO")*0.5 -> 1
A14: 2026 | B14: 22996 | C14: MEDICIÓN RUIDO METRO HUNTER 2026 | D14: D | E14: CONS | F14: CONS | H14: F. Choque | J14: NO APLICA | L14: PENDIENTE | M14: PENDIENTE | O14: NO APLICA | P14: NO APLICA | Q14: NO APLICA | T14: Servicio 02 días | V14: =IFERROR((COUNTIF(J14:S14,"OK")+COUNTIF(J14:S14,"EN PROCESO")*0.5)/(10-COUNTIF(J14:S14,"NO APLICA")-COUNTIF(J14:S14,"DESCARTADA")-COUNTIF(J14:S14,"-")-COUNTIF(J14:S14,"")),"") -> 0 | W14: =IF(ISNUMBER(V14),IF(V14>=0.9,"CONFORME",IF(V14>=0.5,"ALERTA","CRITICO")),IF(F14="CANCELADO","CANCELADO",IF(F14="STAND BY","STAND BY",IF(F14="DESCARTADO","DESCARTADO","S/D")))) -> CRITICO | X14: =10-COUNTIF(J14:S14,"NO APLICA")-COUNTIF(J14:S14,"-")-COUNTIF(J14:S14,"") -> 2 | Y14: =COUNTIF(J14:S14,"OK")+COUNTIF(J14:S14,"EN PROCESO")*0.5 -> 0
A15: 2026 | B15: 22995 | C15: FARMACIAS PERUANAS 2026-2028 | D15: D | E15: SUP | F15: SUP | G15: 46753 | H15: A. Ferrer | I15: César Menez | J15: NO APLICA | L15: PENDIENTE | M15: NO APLICA | O15: NO APLICA | P15: OK | Q15: NO APLICA | S15: OK | V15: =IFERROR((COUNTIF(J15:S15,"OK")+COUNTIF(J15:S15,"EN PROCESO")*0.5)/(10-COUNTIF(J15:S15,"NO APLICA")-COUNTIF(J15:S15,"DESCARTADA")-COUNTIF(J15:S15,"-")-COUNTIF(J15:S15,"")),"") -> 0.66666667 | W15: =IF(ISNUMBER(V15),IF(V15>=0.9,"CONFORME",IF(V15>=0.5,"ALERTA","CRITICO")),IF(F15="CANCELADO","CANCELADO",IF(F15="STAND BY","STAND BY",IF(F15="DESCARTADO","DESCARTADO","S/D")))) -> ALERTA | X15: =10-COUNTIF(J15:S15,"NO APLICA")-COUNTIF(J15:S15,"-")-COUNTIF(J15:S15,"") -> 3 | Y15: =COUNTIF(J15:S15,"OK")+COUNTIF(J15:S15,"EN PROCESO")*0.5 -> 2
A16: 2026 | B16: 22994 | C16: COORDINADORES REAL PLAZA | D16: D | E16: CONS | F16: CONS | G16: 46340 | H16: B. López | I16: Denis Bermudez | J16: NO APLICA | K16: NO APLICA | M16: NO APLICA | N16: NO APLICA | O16: NO APLICA | P16: NO APLICA | Q16: NO APLICA | S16: NO APLICA | V16: =IFERROR((COUNTIF(J16:S16,"OK")+COUNTIF(J16:S16,"EN PROCESO")*0.5)/(10-COUNTIF(J16:S16,"NO APLICA")-COUNTIF(J16:S16,"DESCARTADA")-COUNTIF(J16:S16,"-")-COUNTIF(J16:S16,"")),"") | W16: =IF(ISNUMBER(V16),IF(V16>=0.9,"CONFORME",IF(V16>=0.5,"ALERTA","CRITICO")),IF(F16="CANCELADO","CANCELADO",IF(F16="STAND BY","STAND BY",IF(F16="DESCARTADO","DESCARTADO","S/D")))) -> S/D | X16: =10-COUNTIF(J16:S16,"NO APLICA")-COUNTIF(J16:S16,"-")-COUNTIF(J16:S16,"") -> 0 | Y16: =COUNTIF(J16:S16,"OK")+COUNTIF(J16:S16,"EN PROCESO")*0.5 -> 0
A17: 2026 | B17: 22993 | C17: HVAC RP CAJAMARCA | D17: D | E17: SUP | F17: POR INICIAR | G17: 46223 | H17: M. Becerra | J17: NO APLICA | K17: NO APLICA | M17: NO APLICA | N17: NO APLICA | O17: NO APLICA | Q17: NO APLICA | T17: Fecha de inicio 22-06 | V17: =IFERROR((COUNTIF(J17:S17,"OK")+COUNTIF(J17:S17,"EN PROCESO")*0.5)/(10-COUNTIF(J17:S17,"NO APLICA")-COUNTIF(J17:S17,"DESCARTADA")-COUNTIF(J17:S17,"-")-COUNTIF(J17:S17,"")),"") | W17: =IF(ISNUMBER(V17),IF(V17>=0.9,"CONFORME",IF(V17>=0.5,"ALERTA","CRITICO")),IF(F17="CANCELADO","CANCELADO",IF(F17="STAND BY","STAND BY",IF(F17="DESCARTADO","DESCARTADO","S/D")))) -> S/D | X17: =10-COUNTIF(J17:S17,"NO APLICA")-COUNTIF(J17:S17,"-")-COUNTIF(J17:S17,"") -> 0 | Y17: =COUNTIF(J17:S17,"OK")+COUNTIF(J17:S17,"EN PROCESO")*0.5 -> 0
A18: 2026 | B18: 22992 | C18: 03 SEDES AREQUIPA UTP | D18: D | E18: SUP | F18: SUP | G18: 46195 | H18: B. López | I18: Dushan Ibarra / Juan Vizcarra | J18: NO APLICA | L18: PENDIENTE | M18: NO APLICA | N18: NO APLICA | O18: NO APLICA | P18: OK | Q18: NO APLICA | S18: NO APLICA | V18: =IFERROR((COUNTIF(J18:S18,"OK")+COUNTIF(J18:S18,"EN PROCESO")*0.5)/(10-COUNTIF(J18:S18,"NO APLICA")-COUNTIF(J18:S18,"DESCARTADA")-COUNTIF(J18:S18,"-")-COUNTIF(J18:S18,"")),"") -> 0.5 | W18: =IF(ISNUMBER(V18),IF(V18>=0.9,"CONFORME",IF(V18>=0.5,"ALERTA","CRITICO")),IF(F18="CANCELADO","CANCELADO",IF(F18="STAND BY","STAND BY",IF(F18="DESCARTADO","DESCARTADO","S/D")))) -> ALERTA | X18: =10-COUNTIF(J18:S18,"NO APLICA")-COUNTIF(J18:S18,"-")-COUNTIF(J18:S18,"") -> 2 | Y18: =COUNTIF(J18:S18,"OK")+COUNTIF(J18:S18,"EN PROCESO")*0.5 -> 1
A19: 2026 | B19: 22991 | C19: TALLERES CRC LA JOYA FESA | D19: C | E19: SUP | F19: SUP | G19: 46216 | H19: F. Choque | I19: Santiago Guzmán | J19: PENDIENTE | L19: PENDIENTE | M19: NO APLICA | N19: NO APLICA | P19: OK | Q19: OK | V19: =IFERROR((COUNTIF(J19:S19,"OK")+COUNTIF(J19:S19,"EN PROCESO")*0.5)/(10-COUNTIF(J19:S19,"NO APLICA")-COUNTIF(J19:S19,"DESCARTADA")-COUNTIF(J19:S19,"-")-COUNTIF(J19:S19,"")),"") -> 0.5 | W19: =IF(ISNUMBER(V19),IF(V19>=0.9,"CONFORME",IF(V19>=0.5,"ALERTA","CRITICO")),IF(F19="CANCELADO","CANCELADO",IF(F19="STAND BY","STAND BY",IF(F19="DESCARTADO","DESCARTADO","S/D")))) -> ALERTA | X19: =10-COUNTIF(J19:S19,"NO APLICA")-COUNTIF(J19:S19,"-")-COUNTIF(J19:S19,"") -> 4 | Y19: =COUNTIF(J19:S19,"OK")+COUNTIF(J19:S19,"EN PROCESO")*0.5 -> 2
A20: 2026 | B20: 22990 | C20: TRABAJOS MENORES TORRE IBK | D20: D | E20: SUP | F20: CERRADO | H20: B. López | J20: NO APLICA | K20: NO APLICA | L20: PENDIENTE | M20: NO APLICA | N20: NO APLICA | O20: NO APLICA | P20: OK | Q20: NO APLICA | R20: NO APLICA | S20: NO APLICA | T20: Alcance 02 visitas | U20: 46177 | V20: =IFERROR((COUNTIF(J20:S20,"OK")+COUNTIF(J20:S20,"EN PROCESO")*0.5)/(10-COUNTIF(J20:S20,"NO APLICA")-COUNTIF(J20:S20,"DESCARTADA")-COUNTIF(J20:S20,"-")-COUNTIF(J20:S20,"")),"") -> 0.5 | W20: =IF(ISNUMBER(V20),IF(V20>=0.9,"CONFORME",IF(V20>=0.5,"ALERTA","CRITICO")),IF(F20="CANCELADO","CANCELADO",IF(F20="STAND BY","STAND BY",IF(F20="DESCARTADO","DESCARTADO","S/D")))) -> ALERTA | X20: =10-COUNTIF(J20:S20,"NO APLICA")-COUNTIF(J20:S20,"-")-COUNTIF(J20:S20,"") -> 2 | Y20: =COUNTIF(J20:S20,"OK")+COUNTIF(J20:S20,"EN PROCESO")*0.5 -> 1
A21: 2026 | B21: 22989 | C21: REFORZAMIENTO EST PTAR SAN CLARA | D21: D | E21: SUP | F21: SUP | G21: 46188 | H21: B. López | I21: Pablo Duran | J21: NO APLICA | L21: PENDIENTE | M21: NO APLICA | N21: NO APLICA | O21: NO APLICA | P21: OK | Q21: NO APLICA | S21: NO APLICA | T21: Fin del servicio 16-05 | V21: =IFERROR((COUNTIF(J21:S21,"OK")+COUNTIF(J21:S21,"EN PROCESO")*0.5)/(10-COUNTIF(J21:S21,"NO APLICA")-COUNTIF(J21:S21,"DESCARTADA")-COUNTIF(J21:S21,"-")-COUNTIF(J21:S21,"")),"") -> 0.5 | W21: =IF(ISNUMBER(V21),IF(V21>=0.9,"CONFORME",IF(V21>=0.5,"ALERTA","CRITICO")),IF(F21="CANCELADO","CANCELADO",IF(F21="STAND BY","STAND BY",IF(F21="DESCARTADO","DESCARTADO","S/D")))) -> ALERTA | X21: =10-COUNTIF(J21:S21,"NO APLICA")-COUNTIF(J21:S21,"-")-COUNTIF(J21:S21,"") -> 2 | Y21: =COUNTIF(J21:S21,"OK")+COUNTIF(J21:S21,"EN PROCESO")*0.5 -> 1
A22: 2026 | B22: 22988 | C22: AUDITORIA ET MALL PLAZA TRUJILLO | D22: D | E22: RI | F22: CERRADO | H22: B. López | J22: NO APLICA | K22: PENDIENTE | L22: PENDIENTE | M22: PENDIENTE | N22: PENDIENTE | O22: NO APLICA | P22: NO APLICA | Q22: NO APLICA | R22: NO APLICA | S22: OK | T22: Proveedor Alfarero | U22: 46177 | V22: =IFERROR((COUNTIF(J22:S22,"OK")+COUNTIF(J22:S22,"EN PROCESO")*0.5)/(10-COUNTIF(J22:S22,"NO APLICA")-COUNTIF(J22:S22,"DESCARTADA")-COUNTIF(J22:S22,"-")-COUNTIF(J22:S22,"")),"") -> 0.2 | W22: =IF(ISNUMBER(V22),IF(V22>=0.9,"CONFORME",IF(V22>=0.5,"ALERTA","CRITICO")),IF(F22="CANCELADO","CANCELADO",IF(F22="STAND BY","STAND BY",IF(F22="DESCARTADO","DESCARTADO","S/D")))) -> CRITICO | X22: =10-COUNTIF(J22:S22,"NO APLICA")-COUNTIF(J22:S22,"-")-COUNTIF(J22:S22,"") -> 5 | Y22: =COUNTIF(J22:S22,"OK")+COUNTIF(J22:S22,"EN PROCESO")*0.5 -> 1
A23: 2026 | B23: 22987 | C23: DIRECTIVAS PROYECTOS AIJC LAP - FASE 03 | D23: A | E23: CONS | F23: CONS | G23: 46356 | H23: A. Ferrer | I23: Lorelay Dextre | J23: PENDIENTE | L23: PENDIENTE | M23: NO APLICA | P23: NO APLICA | Q23: OK | V23: =IFERROR((COUNTIF(J23:S23,"OK")+COUNTIF(J23:S23,"EN PROCESO")*0.5)/(10-COUNTIF(J23:S23,"NO APLICA")-COUNTIF(J23:S23,"DESCARTADA")-COUNTIF(J23:S23,"-")-COUNTIF(J23:S23,"")),"") -> 0.33333333 | W23: =IF(ISNUMBER(V23),IF(V23>=0.9,"CONFORME",IF(V23>=0.5,"ALERTA","CRITICO")),IF(F23="CANCELADO","CANCELADO",IF(F23="STAND BY","STAND BY",IF(F23="DESCARTADO","DESCARTADO","S/D")))) -> CRITICO | X23: =10-COUNTIF(J23:S23,"NO APLICA")-COUNTIF(J23:S23,"-")-COUNTIF(J23:S23,"") -> 3 | Y23: =COUNTIF(J23:S23,"OK")+COUNTIF(J23:S23,"EN PROCESO")*0.5 -> 1
A24: 2026 | B24: 22986 | C24: EXPEDIENTE ITSE PRECOR CHILCA | D24: D | E24: CONS | F24: CIERRE | H24: M. Becerra | J24: NO APLICA | K24: PENDIENTE | L24: PENDIENTE | M24: NO APLICA | N24: NO APLICA | O24: NO APLICA | P24: NO APLICA | Q24: NO APLICA | R24: NO APLICA | V24: =IFERROR((COUNTIF(J24:S24,"OK")+COUNTIF(J24:S24,"EN PROCESO")*0.5)/(10-COUNTIF(J24:S24,"NO APLICA")-COUNTIF(J24:S24,"DESCARTADA")-COUNTIF(J24:S24,"-")-COUNTIF(J24:S24,"")),"") -> 0 | W24: =IF(ISNUMBER(V24),IF(V24>=0.9,"CONFORME",IF(V24>=0.5,"ALERTA","CRITICO")),IF(F24="CANCELADO","CANCELADO",IF(F24="STAND BY","STAND BY",IF(F24="DESCARTADO","DESCARTADO","S/D")))) -> CRITICO | X24: =10-COUNTIF(J24:S24,"NO APLICA")-COUNTIF(J24:S24,"-")-COUNTIF(J24:S24,"") -> 2 | Y24: =COUNTIF(J24:S24,"OK")+COUNTIF(J24:S24,"EN PROCESO")*0.5 -> 0
A25: 2026 | B25: 22985 | C25: LICITACIÓN UPN ICA | D25: D | E25: LIC | F25: LIC | G25: 46173 | H25: F. Choque | J25: NO APLICA | L25: PENDIENTE | M25: NO APLICA | N25: NO APLICA | O25: NO APLICA | P25: NO APLICA | Q25: NO APLICA | V25: =IFERROR((COUNTIF(J25:S25,"OK")+COUNTIF(J25:S25,"EN PROCESO")*0.5)/(10-COUNTIF(J25:S25,"NO APLICA")-COUNTIF(J25:S25,"DESCARTADA")-COUNTIF(J25:S25,"-")-COUNTIF(J25:S25,"")),"") -> 0 | W25: =IF(ISNUMBER(V25),IF(V25>=0.9,"CONFORME",IF(V25>=0.5,"ALERTA","CRITICO")),IF(F25="CANCELADO","CANCELADO",IF(F25="STAND BY","STAND BY",IF(F25="DESCARTADO","DESCARTADO","S/D")))) -> CRITICO | X25: =10-COUNTIF(J25:S25,"NO APLICA")-COUNTIF(J25:S25,"-")-COUNTIF(J25:S25,"") -> 1 | Y25: =COUNTIF(J25:S25,"OK")+COUNTIF(J25:S25,"EN PROCESO")*0.5 -> 0
A26: 2026 | B26: 22984 | C26: IISS TORRE INTERBANK | D26: D | E26: SUP | F26: CIERRE | H26: B. López | J26: NO APLICA | K26: PENDIENTE | L26: PENDIENTE | M26: NO APLICA | N26: NO APLICA | O26: NO APLICA | P26: OK | Q26: NO APLICA | R26: PENDIENTE | S26: NO APLICA | T26: Fecha de inicio 24-02 Se realizó la recepción provisional Informes no se enviaron de manera formal por correo. | U26: 46177 | V26: =IFERROR((COUNTIF(J26:S26,"OK")+COUNTIF(J26:S26,"EN PROCESO")*0.5)/(10-COUNTIF(J26:S26,"NO APLICA")-COUNTIF(J26:S26,"DESCARTADA")-COUNTIF(J26:S26,"-")-COUNTIF(J26:S26,"")),"") -> 0.25 | W26: =IF(ISNUMBER(V26),IF(V26>=0.9,"CONFORME",IF(V26>=0.5,"ALERTA","CRITICO")),IF(F26="CANCELADO","CANCELADO",IF(F26="STAND BY","STAND BY",IF(F26="DESCARTADO","DESCARTADO","S/D")))) -> CRITICO | X26: =10-COUNTIF(J26:S26,"NO APLICA")-COUNTIF(J26:S26,"-")-COUNTIF(J26:S26,"") -> 4 | Y26: =COUNTIF(J26:S26,"OK")+COUNTIF(J26:S26,"EN PROCESO")*0.5 -> 1
A27: 2026 | B27: 22983 | C27: HU LAS HIGUERAS- REDES DE IMPULSIÓN | D27: D | E27: SUP | F27: SUP | G27: 46174 | H27: B. López | I27: Andrés Fernández | J27: NO APLICA | L27: PENDIENTE | M27: NO APLICA | N27: NO APLICA | O27: NO APLICA | P27: OK | Q27: OK | V27: =IFERROR((COUNTIF(J27:S27,"OK")+COUNTIF(J27:S27,"EN PROCESO")*0.5)/(10-COUNTIF(J27:S27,"NO APLICA")-COUNTIF(J27:S27,"DESCARTADA")-COUNTIF(J27:S27,"-")-COUNTIF(J27:S27,"")),"") -> 0.66666667 | W27: =IF(ISNUMBER(V27),IF(V27>=0.9,"CONFORME",IF(V27>=0.5,"ALERTA","CRITICO")),IF(F27="CANCELADO","CANCELADO",IF(F27="STAND BY","STAND BY",IF(F27="DESCARTADO","DESCARTADO","S/D")))) -> ALERTA | X27: =10-COUNTIF(J27:S27,"NO APLICA")-COUNTIF(J27:S27,"-")-COUNTIF(J27:S27,"") -> 3 | Y27: =COUNTIF(J27:S27,"OK")+COUNTIF(J27:S27,"EN PROCESO")*0.5 -> 2
A28: 2026 | B28: 22982 | C28: PAVIMENTACIÓN ENRIQUE MEIGSS - PLANTA DUEÑAS | D28: D | E28: SUP | F28: CANCELADO | H28: B. López | J28: NO APLICA | K28: NO APLICA | L28: NO APLICA | M28: NO APLICA | N28: NO APLICA | O28: NO APLICA | P28: NO APLICA | Q28: NO APLICA | R28: NO APLICA | S28: NO APLICA | T28: Solo visitas. Proveedor externo Proyecto cancelado, no se inició servicio. | V28: =IFERROR((COUNTIF(J28:S28,"OK")+COUNTIF(J28:S28,"EN PROCESO")*0.5)/(10-COUNTIF(J28:S28,"NO APLICA")-COUNTIF(J28:S28,"DESCARTADA")-COUNTIF(J28:S28,"-")-COUNTIF(J28:S28,"")),"") | W28: =IF(ISNUMBER(V28),IF(V28>=0.9,"CONFORME",IF(V28>=0.5,"ALERTA","CRITICO")),IF(F28="CANCELADO","CANCELADO",IF(F28="STAND BY","STAND BY",IF(F28="DESCARTADO","DESCARTADO","S/D")))) -> CANCELADO | X28: =10-COUNTIF(J28:S28,"NO APLICA")-COUNTIF(J28:S28,"-")-COUNTIF(J28:S28,"") -> 0 | Y28: =COUNTIF(J28:S28,"OK")+COUNTIF(J28:S28,"EN PROCESO")*0.5 -> 0
A29: 2026 | B29: 22981 | C29: UTP TACNA | D29: D | E29: CONS | F29: CERRADO | H29: B. López | J29: NO APLICA | K29: NO APLICA | L29: PENDIENTE | M29: NO APLICA | N29: NO APLICA | O29: NO APLICA | P29: NO APLICA | Q29: NO APLICA | R29: NO APLICA | S29: NO APLICA | T29: Visita 01 día. | U29: 46177 | V29: =IFERROR((COUNTIF(J29:S29,"OK")+COUNTIF(J29:S29,"EN PROCESO")*0.5)/(10-COUNTIF(J29:S29,"NO APLICA")-COUNTIF(J29:S29,"DESCARTADA")-COUNTIF(J29:S29,"-")-COUNTIF(J29:S29,"")),"") -> 0 | W29: =IF(ISNUMBER(V29),IF(V29>=0.9,"CONFORME",IF(V29>=0.5,"ALERTA","CRITICO")),IF(F29="CANCELADO","CANCELADO",IF(F29="STAND BY","STAND BY",IF(F29="DESCARTADO","DESCARTADO","S/D")))) -> CRITICO | X29: =10-COUNTIF(J29:S29,"NO APLICA")-COUNTIF(J29:S29,"-")-COUNTIF(J29:S29,"") -> 1 | Y29: =COUNTIF(J29:S29,"OK")+COUNTIF(J29:S29,"EN PROCESO")*0.5 -> 0
A30: 2026 | B30: 22980 | C30: REFORZAMIENTO ESTRUCTURAL ALAMEDA PLAZA | D30: D | E30: ING | F30: CERRADO | H30: F. Choque | J30: NO APLICA | K30: OK | L30: PENDIENTE | M30: NO APLICA | N30: NO APLICA | O30: NO APLICA | P30: NO APLICA | Q30: NO APLICA | R30: PENDIENTE | S30: NO APLICA | T30: La ingeniería se desarolla con personal de casa Fecha fin aprox 15-03 | V30: =IFERROR((COUNTIF(J30:S30,"OK")+COUNTIF(J30:S30,"EN PROCESO")*0.5)/(10-COUNTIF(J30:S30,"NO APLICA")-COUNTIF(J30:S30,"DESCARTADA")-COUNTIF(J30:S30,"-")-COUNTIF(J30:S30,"")),"") -> 0.33333333 | W30: =IF(ISNUMBER(V30),IF(V30>=0.9,"CONFORME",IF(V30>=0.5,"ALERTA","CRITICO")),IF(F30="CANCELADO","CANCELADO",IF(F30="STAND BY","STAND BY",IF(F30="DESCARTADO","DESCARTADO","S/D")))) -> CRITICO | X30: =10-COUNTIF(J30:S30,"NO APLICA")-COUNTIF(J30:S30,"-")-COUNTIF(J30:S30,"") -> 3 | Y30: =COUNTIF(J30:S30,"OK")+COUNTIF(J30:S30,"EN PROCESO")*0.5 -> 1
A31: 2026 | B31: 22979 | C31: NUEVO PABELLÓN UMA SJL | D31: A | E31: RI, LIC, SUP | F31: RI | G31: 46538 | H31: B. López | J31: PENDIENTE | L31: PENDIENTE | M31: NO APLICA | S31: NO APLICA | T31: RI: evaluación de costos de las soluciones de ingeniería que propone la gerencia VITAL. | V31: =IFERROR((COUNTIF(J31:S31,"OK")+COUNTIF(J31:S31,"EN PROCESO")*0.5)/(10-COUNTIF(J31:S31,"NO APLICA")-COUNTIF(J31:S31,"DESCARTADA")-COUNTIF(J31:S31,"-")-COUNTIF(J31:S31,"")),"") -> 0 | W31: =IF(ISNUMBER(V31),IF(V31>=0.9,"CONFORME",IF(V31>=0.5,"ALERTA","CRITICO")),IF(F31="CANCELADO","CANCELADO",IF(F31="STAND BY","STAND BY",IF(F31="DESCARTADO","DESCARTADO","S/D")))) -> CRITICO | X31: =10-COUNTIF(J31:S31,"NO APLICA")-COUNTIF(J31:S31,"-")-COUNTIF(J31:S31,"") -> 2 | Y31: =COUNTIF(J31:S31,"OK")+COUNTIF(J31:S31,"EN PROCESO")*0.5 -> 0
A32: 2026 | B32: 22978 | C32: AGENCIA BCP TOTTUS PUENTE PIEDRA | D32: D | E32: SUP | F32: CERRADO | H32: F. Choque | I32: Edith Gutierrez | J32: NO APLICA | K32: PENDIENTE | L32: PENDIENTE | M32: NO APLICA | N32: NO APLICA | O32: NO APLICA | P32: OK | Q32: NO APLICA | R32: OK | S32: NO APLICA | V32: =IFERROR((COUNTIF(J32:S32,"OK")+COUNTIF(J32:S32,"EN PROCESO")*0.5)/(10-COUNTIF(J32:S32,"NO APLICA")-COUNTIF(J32:S32,"DESCARTADA")-COUNTIF(J32:S32,"-")-COUNTIF(J32:S32,"")),"") -> 0.5 | W32: =IF(ISNUMBER(V32),IF(V32>=0.9,"CONFORME",IF(V32>=0.5,"ALERTA","CRITICO")),IF(F32="CANCELADO","CANCELADO",IF(F32="STAND BY","STAND BY",IF(F32="DESCARTADO","DESCARTADO","S/D")))) -> ALERTA | X32: =10-COUNTIF(J32:S32,"NO APLICA")-COUNTIF(J32:S32,"-")-COUNTIF(J32:S32,"") -> 4 | Y32: =COUNTIF(J32:S32,"OK")+COUNTIF(J32:S32,"EN PROCESO")*0.5 -> 2
A33: 2025 | B33: 22977 | C33: ASCENSORES 15 SEDES INNOVA SCHOOL | D33: D | E33: ING | F33: CERRADO | H33: F. Choque | J33: NO APLICA | K33: OK | L33: PENDIENTE | M33: PENDIENTE | N33: PENDIENTE | O33: NO APLICA | P33: NO APLICA | Q33: NO APLICA | R33: OK | V33: =IFERROR((COUNTIF(J33:S33,"OK")+COUNTIF(J33:S33,"EN PROCESO")*0.5)/(10-COUNTIF(J33:S33,"NO APLICA")-COUNTIF(J33:S33,"DESCARTADA")-COUNTIF(J33:S33,"-")-COUNTIF(J33:S33,"")),"") -> 0.4 | W33: =IF(ISNUMBER(V33),IF(V33>=0.9,"CONFORME",IF(V33>=0.5,"ALERTA","CRITICO")),IF(F33="CANCELADO","CANCELADO",IF(F33="STAND BY","STAND BY",IF(F33="DESCARTADO","DESCARTADO","S/D")))) -> CRITICO | X33: =10-COUNTIF(J33:S33,"NO APLICA")-COUNTIF(J33:S33,"-")-COUNTIF(J33:S33,"") -> 5 | Y33: =COUNTIF(J33:S33,"OK")+COUNTIF(J33:S33,"EN PROCESO")*0.5 -> 2
A34: 2025 | B34: 22976 | C34: AMPLIACIÓN OFICINA FERREYROS TOQUEPALA CUAJONE | D34: C | E34: LIC, SUP | F34: CANCELADO | H34: F. Choque | J34: NO APLICA | K34: NO APLICA | L34: NO APLICA | M34: NO APLICA | N34: NO APLICA | O34: NO APLICA | P34: NO APLICA | Q34: NO APLICA | R34: NO APLICA | S34: NO APLICA | T34: Proyecto stand by | V34: =IFERROR((COUNTIF(J34:S34,"OK")+COUNTIF(J34:S34,"EN PROCESO")*0.5)/(10-COUNTIF(J34:S34,"NO APLICA")-COUNTIF(J34:S34,"DESCARTADA")-COUNTIF(J34:S34,"-")-COUNTIF(J34:S34,"")),"") | W34: =IF(ISNUMBER(V34),IF(V34>=0.9,"CONFORME",IF(V34>=0.5,"ALERTA","CRITICO")),IF(F34="CANCELADO","CANCELADO",IF(F34="STAND BY","STAND BY",IF(F34="DESCARTADO","DESCARTADO","S/D")))) -> CANCELADO | X34: =10-COUNTIF(J34:S34,"NO APLICA")-COUNTIF(J34:S34,"-")-COUNTIF(J34:S34,"") -> 0 | Y34: =COUNTIF(J34:S34,"OK")+COUNTIF(J34:S34,"EN PROCESO")*0.5 -> 0
A35: 2026 | B35: 22975 | C35: REVISIÓN EXPEDIENTES MIFARMA CENCO | D35: D | E35: RI | F35: RI | G35: 46203 | H35: M. Becerra | J35: NO APLICA | L35: PENDIENTE | O35: NO APLICA | P35: NO APLICA | Q35: NO APLICA | U35: 45978 | V35: =IFERROR((COUNTIF(J35:S35,"OK")+COUNTIF(J35:S35,"EN PROCESO")*0.5)/(10-COUNTIF(J35:S35,"NO APLICA")-COUNTIF(J35:S35,"DESCARTADA")-COUNTIF(J35:S35,"-")-COUNTIF(J35:S35,"")),"") -> 0 | W35: =IF(ISNUMBER(V35),IF(V35>=0.9,"CONFORME",IF(V35>=0.5,"ALERTA","CRITICO")),IF(F35="CANCELADO","CANCELADO",IF(F35="STAND BY","STAND BY",IF(F35="DESCARTADO","DESCARTADO","S/D")))) -> CRITICO | X35: =10-COUNTIF(J35:S35,"NO APLICA")-COUNTIF(J35:S35,"-")-COUNTIF(J35:S35,"") -> 1 | Y35: =COUNTIF(J35:S35,"OK")+COUNTIF(J35:S35,"EN PROCESO")*0.5 -> 0
A36: 2025 | B36: 22974 | C36: CAMBIO TECNOLOGÍA HVAC PAB. I UPC MONTERRICO | D36: D | E36: SUP | F36: CERRADO | H36: M. Becerra | J36: NO APLICA | K36: PENDIENTE | L36: PENDIENTE | M36: NO APLICA | N36: NO APLICA | O36: NO APLICA | P36: OK | Q36: NO APLICA | R36: OK | T36: Inicio obra 06-11-25 | U36: 45978 | V36: =IFERROR((COUNTIF(J36:S36,"OK")+COUNTIF(J36:S36,"EN PROCESO")*0.5)/(10-COUNTIF(J36:S36,"NO APLICA")-COUNTIF(J36:S36,"DESCARTADA")-COUNTIF(J36:S36,"-")-COUNTIF(J36:S36,"")),"") -> 0.5 | W36: =IF(ISNUMBER(V36),IF(V36>=0.9,"CONFORME",IF(V36>=0.5,"ALERTA","CRITICO")),IF(F36="CANCELADO","CANCELADO",IF(F36="STAND BY","STAND BY",IF(F36="DESCARTADO","DESCARTADO","S/D")))) -> ALERTA | X36: =10-COUNTIF(J36:S36,"NO APLICA")-COUNTIF(J36:S36,"-")-COUNTIF(J36:S36,"") -> 4 | Y36: =COUNTIF(J36:S36,"OK")+COUNTIF(J36:S36,"EN PROCESO")*0.5 -> 2
A37: 2026 | B37: 22973 | C37: OUTLET JOCKEY PLAZA LOTE H | D37: A | E37: GP, SUP | F37: SUP | G37: 46356 | H37: A. Ferrer | I37: Raúl Ávalos | J37: PENDIENTE | L37: PENDIENTE | M37: NO APLICA | P37: OK | Q37: OK | S37: NO APLICA | T37: GP: considera la revisión del expediente técnico y el soporte en el proceso de licitación, ambos ejecutados por el cliente. Servidor sin información Obra inicia en febrero 26 aprox. | V37: =IFERROR((COUNTIF(J37:S37,"OK")+COUNTIF(J37:S37,"EN PROCESO")*0.5)/(10-COUNTIF(J37:S37,"NO APLICA")-COUNTIF(J37:S37,"DESCARTADA")-COUNTIF(J37:S37,"-")-COUNTIF(J37:S37,"")),"") -> 0.5 | W37: =IF(ISNUMBER(V37),IF(V37>=0.9,"CONFORME",IF(V37>=0.5,"ALERTA","CRITICO")),IF(F37="CANCELADO","CANCELADO",IF(F37="STAND BY","STAND BY",IF(F37="DESCARTADO","DESCARTADO","S/D")))) -> ALERTA | X37: =10-COUNTIF(J37:S37,"NO APLICA")-COUNTIF(J37:S37,"-")-COUNTIF(J37:S37,"") -> 4 | Y37: =COUNTIF(J37:S37,"OK")+COUNTIF(J37:S37,"EN PROCESO")*0.5 -> 2
A38: 2026 | B38: 22972 | C38: PACKING ARÁNDANOS PISCO VANGUARD - INGENIERIA | D38: A | E38: ING | F38: ING | H38: M. Becerra | J38: PENDIENTE | L38: PENDIENTE | M38: PENDIENTE | P38: NO APLICA | Q38: PENDIENTE | T38: Supendido | U38: 45978 | V38: =IFERROR((COUNTIF(J38:S38,"OK")+COUNTIF(J38:S38,"EN PROCESO")*0.5)/(10-COUNTIF(J38:S38,"NO APLICA")-COUNTIF(J38:S38,"DESCARTADA")-COUNTIF(J38:S38,"-")-COUNTIF(J38:S38,"")),"") -> 0 | W38: =IF(ISNUMBER(V38),IF(V38>=0.9,"CONFORME",IF(V38>=0.5,"ALERTA","CRITICO")),IF(F38="CANCELADO","CANCELADO",IF(F38="STAND BY","STAND BY",IF(F38="DESCARTADO","DESCARTADO","S/D")))) -> CRITICO | X38: =10-COUNTIF(J38:S38,"NO APLICA")-COUNTIF(J38:S38,"-")-COUNTIF(J38:S38,"") -> 4 | Y38: =COUNTIF(J38:S38,"OK")+COUNTIF(J38:S38,"EN PROCESO")*0.5 -> 0
A39: 2025 | B39: 22971 | C39: RIEGO PACKING PISCO VANGUARD | D39: D | E39: SUP | F39: CERRADO | H39: P. Lavado | I39: Eloy Meza | J39: NO APLICA | K39: PENDIENTE | L39: PENDIENTE | M39: NO APLICA | N39: NO APLICA | O39: NO APLICA | P39: PENDIENTE | Q39: NO APLICA | R39: NO APLICA | V39: =IFERROR((COUNTIF(J39:S39,"OK")+COUNTIF(J39:S39,"EN PROCESO")*0.5)/(10-COUNTIF(J39:S39,"NO APLICA")-COUNTIF(J39:S39,"DESCARTADA")-COUNTIF(J39:S39,"-")-COUNTIF(J39:S39,"")),"") -> 0 | W39: =IF(ISNUMBER(V39),IF(V39>=0.9,"CONFORME",IF(V39>=0.5,"ALERTA","CRITICO")),IF(F39="CANCELADO","CANCELADO",IF(F39="STAND BY","STAND BY",IF(F39="DESCARTADO","DESCARTADO","S/D")))) -> CRITICO | X39: =10-COUNTIF(J39:S39,"NO APLICA")-COUNTIF(J39:S39,"-")-COUNTIF(J39:S39,"") -> 3 | Y39: =COUNTIF(J39:S39,"OK")+COUNTIF(J39:S39,"EN PROCESO")*0.5 -> 0
A40: 2025 | B40: 22970 | C40: AGENCIA BCP PEDRO RUIZ CHICLAYO | D40: D | E40: SUP | F40: CERRADO | H40: F. Choque | J40: NO APLICA | K40: PENDIENTE | L40: PENDIENTE | M40: NO APLICA | N40: NO APLICA | O40: NO APLICA | P40: OK | Q40: NO APLICA | R40: OK | S40: NO APLICA | U40: 45975 | V40: =IFERROR((COUNTIF(J40:S40,"OK")+COUNTIF(J40:S40,"EN PROCESO")*0.5)/(10-COUNTIF(J40:S40,"NO APLICA")-COUNTIF(J40:S40,"DESCARTADA")-COUNTIF(J40:S40,"-")-COUNTIF(J40:S40,"")),"") -> 0.5 | W40: =IF(ISNUMBER(V40),IF(V40>=0.9,"CONFORME",IF(V40>=0.5,"ALERTA","CRITICO")),IF(F40="CANCELADO","CANCELADO",IF(F40="STAND BY","STAND BY",IF(F40="DESCARTADO","DESCARTADO","S/D")))) -> ALERTA | X40: =10-COUNTIF(J40:S40,"NO APLICA")-COUNTIF(J40:S40,"-")-COUNTIF(J40:S40,"") -> 4 | Y40: =COUNTIF(J40:S40,"OK")+COUNTIF(J40:S40,"EN PROCESO")*0.5 -> 2
...

Sheet DASHBOARD_KPIs
A1: DASHBOARD DE SEGUIMIENTO DE PROYECTOS
A2: Actualizado 29/05/2026 · CONFORME ≥ 90% | EN RIESGO 50–89% | CRÍTICO < 50%
B3: 🔍 FILTRAR POR AÑO DE CIERRE: | D3: 0 | E3: =IF(D3=0,">0","="&D3) -> >0 | F3: ← Escribir: 0=TODOS / 2024 / 2025 / 2026
B5: 📊 RESUMEN GENERAL DE PROYECTOS
B6: TOTAL PROYECTOS | C6: PROYECTOS ACTIVOS | D6: CERRADOS | E6: CANCELADOS | F6: STAND BY | G6: % SIG PROM.
B7: =COUNTIFS(SEGUIMIENTO_PROYECTOS!$A$5:$A$185,DASHBOARD_KPIs!$E$3) -> 180 | C7: =COUNTIFS(SEGUIMIENTO_PROYECTOS!$A$5:$A$185,DASHBOARD_KPIs!$E$3)-COUNTIFS(SEGUIMIENTO_PROYECTOS!$A$5:$A$185,DASHBOARD_KPIs!$E$3,SEGUIMIENTO_PROYECTOS!$F$5:$F$185,"CERRADO")-COUNTIFS(SEGUIMIENTO_PROYECTOS!$A$5:$A$185,DASHBOARD_KPIs!$E$3,SEGUIMIENTO_PROYECTOS!$F$5:$F$185,"CANCELADO")-COUNTIFS(SEGUIMIENTO_PROYECTOS!$A$5:$A$185,DASHBOARD_KPIs!$E$3,SEGUIMIENTO_PROYECTOS!$F$5:$F$185,"DESCARTADO") -> 46 | D7: =COUNTIFS(SEGUIMIENTO_PROYECTOS!$A$5:$A$185,DASHBOARD_KPIs!$E$3,SEGUIMIENTO_PROYECTOS!$F$5:$F$185,"CERRADO") -> 130 | E7: =COUNTIFS(SEGUIMIENTO_PROYECTOS!$A$5:$A$185,DASHBOARD_KPIs!$E$3,SEGUIMIENTO_PROYECTOS!$F$5:$F$185,"CANCELADO") -> 4 | F7: =COUNTIFS(SEGUIMIENTO_PROYECTOS!$A$5:$A$185,DASHBOARD_KPIs!$E$3,SEGUIMIENTO_PROYECTOS!$F$5:$F$185,"STAND BY") -> 4 | G7: =IFERROR(SUMIFS(SEGUIMIENTO_PROYECTOS!$Y$5:$Y$185,SEGUIMIENTO_PROYECTOS!$A$5:$A$185,DASHBOARD_KPIs!$E$3)/SUMIFS(SEGUIMIENTO_PROYECTOS!$X$5:$X$185,SEGUIMIENTO_PROYECTOS!$A$5:$A$185,DASHBOARD_KPIs!$E$3),"—") -> 0.55511811
B8: En base de datos | C8: Excluye cerrados | D8: Etapa CERRADO | E8: Etapa CANCELADO | F8: Suspendidos | G8: Acumulado todos los proyectos
B11: 🚦 ESTADO GENERAL — DISTRIBUCIÓN
B12: CONFORME | C12: ALERTA | D12: CRITICO | E12: CANCELADO | F12: STAND BY | G12: S/D
B13: =COUNTIFS(SEGUIMIENTO_PROYECTOS!$A$5:$A$185,DASHBOARD_KPIs!$E$3,SEGUIMIENTO_PROYECTOS!$W$5:$W$185,"CONFORME") -> 33 | C13: =COUNTIFS(SEGUIMIENTO_PROYECTOS!$A$5:$A$185,DASHBOARD_KPIs!$E$3,SEGUIMIENTO_PROYECTOS!$W$5:$W$185,"ALERTA") -> 74 | D13: =COUNTIFS(SEGUIMIENTO_PROYECTOS!$A$5:$A$185,DASHBOARD_KPIs!$E$3,SEGUIMIENTO_PROYECTOS!$W$5:$W$185,"CRITICO") -> 62 | E13: =COUNTIFS(SEGUIMIENTO_PROYECTOS!$A$5:$A$185,DASHBOARD_KPIs!$E$3,SEGUIMIENTO_PROYECTOS!$W$5:$W$185,"CANCELADO") -> 3 | F13: =COUNTIFS(SEGUIMIENTO_PROYECTOS!$A$5:$A$185,DASHBOARD_KPIs!$E$3,SEGUIMIENTO_PROYECTOS!$W$5:$W$185,"STAND BY") -> 2 | G13: =COUNTIFS(SEGUIMIENTO_PROYECTOS!$A$5:$A$185,DASHBOARD_KPIs!$E$3,SEGUIMIENTO_PROYECTOS!$W$5:$W$185,"S/D") -> 6
B14: ≥ 90% SIG | C14: 50–89% SIG | D14: < 50% SIG | E14: Etapa CANCELADO | F14: Suspendidos | G14: Sin datos
B17: 📋 SEGUIMIENTO POR ENTREGABLE SIG
B18: ENTREGABLE | C18: APLICA | D18: OK | E18: OK (falta firma) | F18: EN PROCESO | G18: PENDIENTE | H18: NO APLICA | I18: % CUMPL. | J18: ESTADO
B19: FICHA DE PROYECTO | C19: =COUNTIFS(SEGUIMIENTO_PROYECTOS!$A$5:$A$185,DASHBOARD_KPIs!$E$3)-COUNTIFS(SEGUIMIENTO_PROYECTOS!$A$5:$A$185,DASHBOARD_KPIs!$E$3,SEGUIMIENTO_PROYECTOS!$J$5:$J$185,"NO APLICA")-COUNTIFS(SEGUIMIENTO_PROYECTOS!$A$5:$A$185,DASHBOARD_KPIs!$E$3,SEGUIMIENTO_PROYECTOS!$J$5:$J$185,"-")-COUNTIFS(SEGUIMIENTO_PROYECTOS!$A$5:$A$185,DASHBOARD_KPIs!$E$3,SEGUIMIENTO_PROYECTOS!$J$5:$J$185,"") -> 51 | D19: =COUNTIFS(SEGUIMIENTO_PROYECTOS!$A$5:$A$185,DASHBOARD_KPIs!$E$3,SEGUIMIENTO_PROYECTOS!$J$5:$J$185,"OK") -> 18 | E19: =COUNTIFS(SEGUIMIENTO_PROYECTOS!$A$5:$A$185,DASHBOARD_KPIs!$E$3,SEGUIMIENTO_PROYECTOS!$J$5:$J$185,"OK (falta firma)") -> 0 | F19: =COUNTIFS(SEGUIMIENTO_PROYECTOS!$A$5:$A$185,DASHBOARD_KPIs!$E$3,SEGUIMIENTO_PROYECTOS!$J$5:$J$185,"EN PROCESO") -> 4 | G19: =COUNTIFS(SEGUIMIENTO_PROYECTOS!$A$5:$A$185,DASHBOARD_KPIs!$E$3,SEGUIMIENTO_PROYECTOS!$J$5:$J$185,"PENDIENTE") -> 29 | H19: =COUNTIFS(SEGUIMIENTO_PROYECTOS!$A$5:$A$185,DASHBOARD_KPIs!$E$3,SEGUIMIENTO_PROYECTOS!$J$5:$J$185,"NO APLICA") -> 122 | I19: =IFERROR((COUNTIFS(SEGUIMIENTO_PROYECTOS!$A$5:$A$185,DASHBOARD_KPIs!$E$3,SEGUIMIENTO_PROYECTOS!$J$5:$J$185,"OK")+COUNTIFS(SEGUIMIENTO_PROYECTOS!$A$5:$A$185,DASHBOARD_KPIs!$E$3,SEGUIMIENTO_PROYECTOS!$J$5:$J$185,"OK (falta firma)")*0.75+COUNTIFS(SEGUIMIENTO_PROYECTOS!$A$5:$A$185,DASHBOARD_KPIs!$E$3,SEGUIMIENTO_PROYECTOS!$J$5:$J$185,"EN PROCESO")*0.5)/(COUNTIFS(SEGUIMIENTO_PROYECTOS!$A$5:$A$185,DASHBOARD_KPIs!$E$3)-COUNTIFS(SEGUIMIENTO_PROYECTOS!$A$5:$A$185,DASHBOARD_KPIs!$E$3,SEGUIMIENTO_PROYECTOS!$J$5:$J$185,"NO APLICA")-COUNTIFS(SEGUIMIENTO_PROYECTOS!$A$5:$A$185,DASHBOARD_KPIs!$E$3,SEGUIMIENTO_PROYECTOS!$J$5:$J$185,"-")-COUNTIFS(SEGUIMIENTO_PROYECTOS!$A$5:$A$185,DASHBOARD_KPIs!$E$3,SEGUIMIENTO_PROYECTOS!$J$5:$J$185,"")),"") -> 0.39215686 | J19: =IFERROR(IF(I19>=0.9,"CONFORME",IF(I19>=0.5,"ALERTA","CRITICO")),"S/D") -> CRITICO
B20: ACTA DE CONFORMIDAD (ACS) | C20: =COUNTIFS(SEGUIMIENTO_PROYECTOS!$A$5:$A$185,DASHBOARD_KPIs!$E$3)-COUNTIFS(SEGUIMIENTO_PROYECTOS!$A$5:$A$185,DASHBOARD_KPIs!$E$3,SEGUIMIENTO_PROYECTOS!$K$5:$K$185,"NO APLICA")-COUNTIFS(SEGUIMIENTO_PROYECTOS!$A$5:$A$185,DASHBOARD_KPIs!$E$3,SEGUIMIENTO_PROYECTOS!$K$5:$K$185,"-")-COUNTIFS(SEGUIMIENTO_PROYECTOS!$A$5:$A$185,DASHBOARD_KPIs!$E$3,SEGUIMIENTO_PROYECTOS!$K$5:$K$185,"") -> 110 | D20: =COUNTIFS(SEGUIMIENTO_PROYECTOS!$A$5:$A$185,DASHBOARD_KPIs!$E$3,SEGUIMIENTO_PROYECTOS!$K$5:$K$185,"OK") -> 51 | E20: =COUNTIFS(SEGUIMIENTO_PROYECTOS!$A$5:$A$185,DASHBOARD_KPIs!$E$3,SEGUIMIENTO_PROYECTOS!$K$5:$K$185,"OK (falta firma)") -> 0 | F20: =COUNTIFS(SEGUIMIENTO_PROYECTOS!$A$5:$A$185,DASHBOARD_KPIs!$E$3,SEGUIMIENTO_PROYECTOS!$K$5:$K$185,"EN PROCESO") -> 0 | G20: =COUNTIFS(SEGUIMIENTO_PROYECTOS!$A$5:$A$185,DASHBOARD_KPIs!$E$3,SEGUIMIENTO_PROYECTOS!$K$5:$K$185,"PENDIENTE") -> 52 | H20: =COUNTIFS(SEGUIMIENTO_PROYECTOS!$A$5:$A$185,DASHBOARD_KPIs!$E$3,SEGUIMIENTO_PROYECTOS!$K$5:$K$185,"NO APLICA") -> 25 | I20: =IFERROR((COUNTIFS(SEGUIMIENTO_PROYECTOS!$A$5:$A$185,DASHBOARD_KPIs!$E$3,SEGUIMIENTO_PROYECTOS!$K$5:$K$185,"OK")+COUNTIFS(SEGUIMIENTO_PROYECTOS!$A$5:$A$185,DASHBOARD_KPIs!$E$3,SEGUIMIENTO_PROYECTOS!$K$5:$K$185,"OK (falta firma)")*0.75+COUNTIFS(SEGUIMIENTO_PROYECTOS!$A$5:$A$185,DASHBOARD_KPIs!$E$3,SEGUIMIENTO_PROYECTOS!$K$5:$K$185,"EN PROCESO")*0.5)/(COUNTIFS(SEGUIMIENTO_PROYECTOS!$A$5:$A$185,DASHBOARD_KPIs!$E$3)-COUNTIFS(SEGUIMIENTO_PROYECTOS!$A$5:$A$185,DASHBOARD_KPIs!$E$3,SEGUIMIENTO_PROYECTOS!$K$5:$K$185,"NO APLICA")-COUNTIFS(SEGUIMIENTO_PROYECTOS!$A$5:$A$185,DASHBOARD_KPIs!$E$3,SEGUIMIENTO_PROYECTOS!$K$5:$K$185,"-")-COUNTIFS(SEGUIMIENTO_PROYECTOS!$A$5:$A$185,DASHBOARD_KPIs!$E$3,SEGUIMIENTO_PROYECTOS!$K$5:$K$185,"")),"") -> 0.46363636 | J20: =IFERROR(IF(I20>=0.9,"CONFORME",IF(I20>=0.5,"ALERTA","CRITICO")),"S/D") -> CRITICO
B21: ACTUALIZACIÓN SERVIDOR | C21: =COUNTIFS(SEGUIMIENTO_PROYECTOS!$A$5:$A$185,DASHBOARD_KPIs!$E$3)-COUNTIFS(SEGUIMIENTO_PROYECTOS!$A$5:$A$185,DASHBOARD_KPIs!$E$3,SEGUIMIENTO_PROYECTOS!$L$5:$L$185,"NO APLICA")-COUNTIFS(SEGUIMIENTO_PROYECTOS!$A$5:$A$185,DASHBOARD_KPIs!$E$3,SEGUIMIENTO_PROYECTOS!$L$5:$L$185,"-")-COUNTIFS(SEGUIMIENTO_PROYECTOS!$A$5:$A$185,DASHBOARD_KPIs!$E$3,SEGUIMIENTO_PROYECTOS!$L$5:$L$185,"") -> 165 | D21: =COUNTIFS(SEGUIMIENTO_PROYECTOS!$A$5:$A$185,DASHBOARD_KPIs!$E$3,SEGUIMIENTO_PROYECTOS!$L$5:$L$185,"OK") -> 56 | E21: =COUNTIFS(SEGUIMIENTO_PROYECTOS!$A$5:$A$185,DASHBOARD_KPIs!$E$3,SEGUIMIENTO_PROYECTOS!$L$5:$L$185,"OK (falta firma)") -> 0 | F21: =COUNTIFS(SEGUIMIENTO_PROYECTOS!$A$5:$A$185,DASHBOARD_KPIs!$E$3,SEGUIMIENTO_PROYECTOS!$L$5:$L$185,"EN PROCESO") -> 8 | G21: =COUNTIFS(SEGUIMIENTO_PROYECTOS!$A$5:$A$185,DASHBOARD_KPIs!$E$3,SEGUIMIENTO_PROYECTOS!$L$5:$L$185,"PENDIENTE") -> 101 | H21: =COUNTIFS(SEGUIMIENTO_PROYECTOS!$A$5:$A$185,DASHBOARD_KPIs!$E$3,SEGUIMIENTO_PROYECTOS!$L$5:$L$185,"NO APLICA") -> 4 | I21: =IFERROR((COUNTIFS(SEGUIMIENTO_PROYECTOS!$A$5:$A$185,DASHBOARD_KPIs!$E$3,SEGUIMIENTO_PROYECTOS!$L$5:$L$185,"OK")+COUNTIFS(SEGUIMIENTO_PROYECTOS!$A$5:$A$185,DASHBOARD_KPIs!$E$3,SEGUIMIENTO_PROYECTOS!$L$5:$L$185,"OK (falta firma)")*0.75+COUNTIFS(SEGUIMIENTO_PROYECTOS!$A$5:$A$185,DASHBOARD_KPIs!$E$3,SEGUIMIENTO_PROYECTOS!$L$5:$L$185,"EN PROCESO")*0.5)/(COUNTIFS(SEGUIMIENTO_PROYECTOS!$A$5:$A$185,DASHBOARD_KPIs!$E$3)-COUNTIFS(SEGUIMIENTO_PROYECTOS!$A$5:$A$185,DASHBOARD_KPIs!$E$3,SEGUIMIENTO_PROYECTOS!$L$5:$L$185,"NO APLICA")-COUNTIFS(SEGUIMIENTO_PROYECTOS!$A$5:$A$185,DASHBOARD_KPIs!$E$3,SEGUIMIENTO_PROYECTOS!$L$5:$L$185,"-")-COUNTIFS(SEGUIMIENTO_PROYECTOS!$A$5:$A$185,DASHBOARD_KPIs!$E$3,SEGUIMIENTO_PROYECTOS!$L$5:$L$185,"")),"") -> 0.36363636 | J21: =IFERROR(IF(I21>=0.9,"CONFORME",IF(I21>=0.5,"ALERTA","CRITICO")),"S/D") -> CRITICO
B22: EVAL. SELECCIÓN PROV. / CCP | C22: =COUNTIFS(SEGUIMIENTO_PROYECTOS!$A$5:$A$185,DASHBOARD_KPIs!$E$3)-COUNTIFS(SEGUIMIENTO_PROYECTOS!$A$5:$A$185,DASHBOARD_KPIs!$E$3,SEGUIMIENTO_PROYECTOS!$M$5:$M$185,"NO APLICA")-COUNTIFS(SEGUIMIENTO_PROYECTOS!$A$5:$A$185,DASHBOARD_KPIs!$E$3,SEGUIMIENTO_PROYECTOS!$M$5:$M$185,"-")-COUNTIFS(SEGUIMIENTO_PROYECTOS!$A$5:$A$185,DASHBOARD_KPIs!$E$3,SEGUIMIENTO_PROYECTOS!$M$5:$M$185,"") -> 29 | D22: =COUNTIFS(SEGUIMIENTO_PROYECTOS!$A$5:$A$185,DASHBOARD_KPIs!$E$3,SEGUIMIENTO_PROYECTOS!$M$5:$M$185,"OK") -> 8 | E22: =COUNTIFS(SEGUIMIENTO_PROYECTOS!$A$5:$A$185,DASHBOARD_KPIs!$E$3,SEGUIMIENTO_PROYECTOS!$M$5:$M$185,"OK (falta firma)") -> 0 | F22: =COUNTIFS(SEGUIMIENTO_PROYECTOS!$A$5:$A$185,DASHBOARD_KPIs!$E$3,SEGUIMIENTO_PROYECTOS!$M$5:$M$185,"EN PROCESO") -> 1 | G22: =COUNTIFS(SEGUIMIENTO_PROYECTOS!$A$5:$A$185,DASHBOARD_KPIs!$E$3,SEGUIMIENTO_PROYECTOS!$M$5:$M$185,"PENDIENTE") -> 20 | H22: =COUNTIFS(SEGUIMIENTO_PROYECTOS!$A$5:$A$185,DASHBOARD_KPIs!$E$3,SEGUIMIENTO_PROYECTOS!$M$5:$M$185,"NO APLICA") -> 140 | I22: =IFERROR((COUNTIFS(SEGUIMIENTO_PROYECTOS!$A$5:$A$185,DASHBOARD_KPIs!$E$3,SEGUIMIENTO_PROYECTOS!$M$5:$M$185,"OK")+COUNTIFS(SEGUIMIENTO_PROYECTOS!$A$5:$A$185,DASHBOARD_KPIs!$E$3,SEGUIMIENTO_PROYECTOS!$M$5:$M$185,"OK (falta firma)")*0.75+COUNTIFS(SEGUIMIENTO_PROYECTOS!$A$5:$A$185,DASHBOARD_KPIs!$E$3,SEGUIMIENTO_PROYECTOS!$M$5:$M$185,"EN PROCESO")*0.5)/(COUNTIFS(SEGUIMIENTO_PROYECTOS!$A$5:$A$185,DASHBOARD_KPIs!$E$3)-COUNTIFS(SEGUIMIENTO_PROYECTOS!$A$5:$A$185,DASHBOARD_KPIs!$E$3,SEGUIMIENTO_PROYECTOS!$M$5:$M$185,"NO APLICA")-COUNTIFS(SEGUIMIENTO_PROYECTOS!$A$5:$A$185,DASHBOARD_KPIs!$E$3,SEGUIMIENTO_PROYECTOS!$M$5:$M$185,"-")-COUNTIFS(SEGUIMIENTO_PROYECTOS!$A$5:$A$185,DASHBOARD_KPIs!$E$3,SEGUIMIENTO_PROYECTOS!$M$5:$M$185,"")),"") -> 0.29310345 | J22: =IFERROR(IF(I22>=0.9,"CONFORME",IF(I22>=0.5,"ALERTA","CRITICO")),"S/D") -> CRITICO
B23: DESEMPEÑO PROV. (EPSP) | C23: =COUNTIFS(SEGUIMIENTO_PROYECTOS!$A$5:$A$185,DASHBOARD_KPIs!$E$3)-COUNTIFS(SEGUIMIENTO_PROYECTOS!$A$5:$A$185,DASHBOARD_KPIs!$E$3,SEGUIMIENTO_PROYECTOS!$N$5:$N$185,"NO APLICA")-COUNTIFS(SEGUIMIENTO_PROYECTOS!$A$5:$A$185,DASHBOARD_KPIs!$E$3,SEGUIMIENTO_PROYECTOS!$N$5:$N$185,"-")-COUNTIFS(SEGUIMIENTO_PROYECTOS!$A$5:$A$185,DASHBOARD_KPIs!$E$3,SEGUIMIENTO_PROYECTOS!$N$5:$N$185,"") -> 53 | D23: =COUNTIFS(SEGUIMIENTO_PROYECTOS!$A$5:$A$185,DASHBOARD_KPIs!$E$3,SEGUIMIENTO_PROYECTOS!$N$5:$N$185,"OK") -> 35 | E23: =COUNTIFS(SEGUIMIENTO_PROYECTOS!$A$5:$A$185,DASHBOARD_KPIs!$E$3,SEGUIMIENTO_PROYECTOS!$N$5:$N$185,"OK (falta firma)") -> 0 | F23: =COUNTIFS(SEGUIMIENTO_PROYECTOS!$A$5:$A$185,DASHBOARD_KPIs!$E$3,SEGUIMIENTO_PROYECTOS!$N$5:$N$185,"EN PROCESO") -> 0 | G23: =COUNTIFS(SEGUIMIENTO_PROYECTOS!$A$5:$A$185,DASHBOARD_KPIs!$E$3,SEGUIMIENTO_PROYECTOS!$N$5:$N$185,"PENDIENTE") -> 18 | H23: =COUNTIFS(SEGUIMIENTO_PROYECTOS!$A$5:$A$185,DASHBOARD_KPIs!$E$3,SEGUIMIENTO_PROYECTOS!$N$5:$N$185,"NO APLICA") -> 107 | I23: =IFERROR((COUNTIFS(SEGUIMIENTO_PROYECTOS!$A$5:$A$185,DASHBOARD_KPIs!$E$3,SEGUIMIENTO_PROYECTOS!$N$5:$N$185,"OK")+COUNTIFS(SEGUIMIENTO_PROYECTOS!$A$5:$A$185,DASHBOARD_KPIs!$E$3,SEGUIMIENTO_PROYECTOS!$N$5:$N$185,"OK (falta firma)")*0.75+COUNTIFS(SEGUIMIENTO_PROYECTOS!$A$5:$A$185,DASHBOARD_KPIs!$E$3,SEGUIMIENTO_PROYECTOS!$N$5:$N$185,"EN PROCESO")*0.5)/(COUNTIFS(SEGUIMIENTO_PROYECTOS!$A$5:$A$185,DASHBOARD_KPIs!$E$3)-COUNTIFS(SEGUIMIENTO_PROYECTOS!$A$5:$A$185,DASHBOARD_KPIs!$E$3,SEGUIMIENTO_PROYECTOS!$N$5:$N$185,"NO APLICA")-COUNTIFS(SEGUIMIENTO_PROYECTOS!$A$5:$A$185,DASHBOARD_KPIs!$E$3,SEGUIMIENTO_PROYECTOS!$N$5:$N$185,"-")-COUNTIFS(SEGUIMIENTO_PROYECTOS!$A$5:$A$185,DASHBOARD_KPIs!$E$3,SEGUIMIENTO_PROYECTOS!$N$5:$N$185,"")),"") -> 0.66037736 | J23: =IFERROR(IF(I23>=0.9,"CONFORME",IF(I23>=0.5,"ALERTA","CRITICO")),"S/D") -> ALERTA
B24: LECCIONES APRENDIDAS | C24: =COUNTIFS(SEGUIMIENTO_PROYECTOS!$A$5:$A$185,DASHBOARD_KPIs!$E$3)-COUNTIFS(SEGUIMIENTO_PROYECTOS!$A$5:$A$185,DASHBOARD_KPIs!$E$3,SEGUIMIENTO_PROYECTOS!$O$5:$O$185,"NO APLICA")-COUNTIFS(SEGUIMIENTO_PROYECTOS!$A$5:$A$185,DASHBOARD_KPIs!$E$3,SEGUIMIENTO_PROYECTOS!$O$5:$O$185,"-")-COUNTIFS(SEGUIMIENTO_PROYECTOS!$A$5:$A$185,DASHBOARD_KPIs!$E$3,SEGUIMIENTO_PROYECTOS!$O$5:$O$185,"") -> 36 | D24: =COUNTIFS(SEGUIMIENTO_PROYECTOS!$A$5:$A$185,DASHBOARD_KPIs!$E$3,SEGUIMIENTO_PROYECTOS!$O$5:$O$185,"OK") -> 13 | E24: =COUNTIFS(SEGUIMIENTO_PROYECTOS!$A$5:$A$185,DASHBOARD_KPIs!$E$3,SEGUIMIENTO_PROYECTOS!$O$5:$O$185,"OK (falta firma)") -> 0 | F24: =COUNTIFS(SEGUIMIENTO_PROYECTOS!$A$5:$A$185,DASHBOARD_KPIs!$E$3,SEGUIMIENTO_PROYECTOS!$O$5:$O$185,"EN PROCESO") -> 0 | G24: =COUNTIFS(SEGUIMIENTO_PROYECTOS!$A$5:$A$185,DASHBOARD_KPIs!$E$3,SEGUIMIENTO_PROYECTOS!$O$5:$O$185,"PENDIENTE") -> 23 | H24: =COUNTIFS(SEGUIMIENTO_PROYECTOS!$A$5:$A$185,DASHBOARD_KPIs!$E$3,SEGUIMIENTO_PROYECTOS!$O$5:$O$185,"NO APLICA") -> 123 | I24: =IFERROR((COUNTIFS(SEGUIMIENTO_PROYECTOS!$A$5:$A$185,DASHBOARD_KPIs!$E$3,SEGUIMIENTO_PROYECTOS!$O$5:$O$185,"OK")+COUNTIFS(SEGUIMIENTO_PROYECTOS!$A$5:$A$185,DASHBOARD_KPIs!$E$3,SEGUIMIENTO_PROYECTOS!$O$5:$O$185,"OK (falta firma)")*0.75+COUNTIFS(SEGUIMIENTO_PROYECTOS!$A$5:$A$185,DASHBOARD_KPIs!$E$3,SEGUIMIENTO_PROYECTOS!$O$5:$O$185,"EN PROCESO")*0.5)/(COUNTIFS(SEGUIMIENTO_PROYECTOS!$A$5:$A$185,DASHBOARD_KPIs!$E$3)-COUNTIFS(SEGUIMIENTO_PROYECTOS!$A$5:$A$185,DASHBOARD_KPIs!$E$3,SEGUIMIENTO_PROYECTOS!$O$5:$O$185,"NO APLICA")-COUNTIFS(SEGUIMIENTO_PROYECTOS!$A$5:$A$185,DASHBOARD_KPIs!$E$3,SEGUIMIENTO_PROYECTOS!$O$5:$O$185,"-")-COUNTIFS(SEGUIMIENTO_PROYECTOS!$A$5:$A$185,DASHBOARD_KPIs!$E$3,SEGUIMIENTO_PROYECTOS!$O$5:$O$185,"")),"") -> 0.36111111 | J24: =IFERROR(IF(I24>=0.9,"CONFORME",IF(I24>=0.5,"ALERTA","CRITICO")),"S/D") -> CRITICO
B25: REPORTES (RA) | C25: =COUNTIFS(SEGUIMIENTO_PROYECTOS!$A$5:$A$185,DASHBOARD_KPIs!$E$3)-COUNTIFS(SEGUIMIENTO_PROYECTOS!$A$5:$A$185,DASHBOARD_KPIs!$E$3,SEGUIMIENTO_PROYECTOS!$P$5:$P$185,"NO APLICA")-COUNTIFS(SEGUIMIENTO_PROYECTOS!$A$5:$A$185,DASHBOARD_KPIs!$E$3,SEGUIMIENTO_PROYECTOS!$P$5:$P$185,"-")-COUNTIFS(SEGUIMIENTO_PROYECTOS!$A$5:$A$185,DASHBOARD_KPIs!$E$3,SEGUIMIENTO_PROYECTOS!$P$5:$P$185,"") -> 116 | D25: =COUNTIFS(SEGUIMIENTO_PROYECTOS!$A$5:$A$185,DASHBOARD_KPIs!$E$3,SEGUIMIENTO_PROYECTOS!$P$5:$P$185,"OK") -> 92 | E25: =COUNTIFS(SEGUIMIENTO_PROYECTOS!$A$5:$A$185,DASHBOARD_KPIs!$E$3,SEGUIMIENTO_PROYECTOS!$P$5:$P$185,"OK (falta firma)") -> 0 | F25: =COUNTIFS(SEGUIMIENTO_PROYECTOS!$A$5:$A$185,DASHBOARD_KPIs!$E$3,SEGUIMIENTO_PROYECTOS!$P$5:$P$185,"EN PROCESO") -> 0 | G25: =COUNTIFS(SEGUIMIENTO_PROYECTOS!$A$5:$A$185,DASHBOARD_KPIs!$E$3,SEGUIMIENTO_PROYECTOS!$P$5:$P$185,"PENDIENTE") -> 24 | H25: =COUNTIFS(SEGUIMIENTO_PROYECTOS!$A$5:$A$185,DASHBOARD_KPIs!$E$3,SEGUIMIENTO_PROYECTOS!$P$5:$P$185,"NO APLICA") -> 52 | I25: =IFERROR((COUNTIFS(SEGUIMIENTO_PROYECTOS!$A$5:$A$185,DASHBOARD_KPIs!$E$3,SEGUIMIENTO_PROYECTOS!$P$5:$P$185,"OK")+COUNTIFS(SEGUIMIENTO_PROYECTOS!$A$5:$A$185,DASHBOARD_KPIs!$E$3,SEGUIMIENTO_PROYECTOS!$P$5:$P$185,"OK (falta firma)")*0.75+COUNTIFS(SEGUIMIENTO_PROYECTOS!$A$5:$A$185,DASHBOARD_KPIs!$E$3,SEGUIMIENTO_PROYECTOS!$P$5:$P$185,"EN PROCESO")*0.5)/(COUNTIFS(SEGUIMIENTO_PROYECTOS!$A$5:$A$185,DASHBOARD_KPIs!$E$3)-COUNTIFS(SEGUIMIENTO_PROYECTOS!$A$5:$A$185,DASHBOARD_KPIs!$E$3,SEGUIMIENTO_PROYECTOS!$P$5:$P$185,"NO APLICA")-COUNTIFS(SEGUIMIENTO_PROYECTOS!$A$5:$A$185,DASHBOARD_KPIs!$E$3,SEGUIMIENTO_PROYECTOS!$P$5:$P$185,"-")-COUNTIFS(SEGUIMIENTO_PROYECTOS!$A$5:$A$185,DASHBOARD_KPIs!$E$3,SEGUIMIENTO_PROYECTOS!$P$5:$P$185,"")),"") -> 0.79310345 | J25: =IFERROR(IF(I25>=0.9,"CONFORME",IF(I25>=0.5,"ALERTA","CRITICO")),"S/D") -> ALERTA
B26: ACTAS DE REUNIÓN | C26: =COUNTIFS(SEGUIMIENTO_PROYECTOS!$A$5:$A$185,DASHBOARD_KPIs!$E$3)-COUNTIFS(SEGUIMIENTO_PROYECTOS!$A$5:$A$185,DASHBOARD_KPIs!$E$3,SEGUIMIENTO_PROYECTOS!$Q$5:$Q$185,"NO APLICA")-COUNTIFS(SEGUIMIENTO_PROYECTOS!$A$5:$A$185,DASHBOARD_KPIs!$E$3,SEGUIMIENTO_PROYECTOS!$Q$5:$Q$185,"-")-COUNTIFS(SEGUIMIENTO_PROYECTOS!$A$5:$A$185,DASHBOARD_KPIs!$E$3,SEGUIMIENTO_PROYECTOS!$Q$5:$Q$185,"") -> 64 | D26: =COUNTIFS(SEGUIMIENTO_PROYECTOS!$A$5:$A$185,DASHBOARD_KPIs!$E$3,SEGUIMIENTO_PROYECTOS!$Q$5:$Q$185,"OK") -> 51 | E26: =COUNTIFS(SEGUIMIENTO_PROYECTOS!$A$5:$A$185,DASHBOARD_KPIs!$E$3,SEGUIMIENTO_PROYECTOS!$Q$5:$Q$185,"OK (falta firma)") -> 0 | F26: =COUNTIFS(SEGUIMIENTO_PROYECTOS!$A$5:$A$185,DASHBOARD_KPIs!$E$3,SEGUIMIENTO_PROYECTOS!$Q$5:$Q$185,"EN PROCESO") -> 0 | G26: =COUNTIFS(SEGUIMIENTO_PROYECTOS!$A$5:$A$185,DASHBOARD_KPIs!$E$3,SEGUIMIENTO_PROYECTOS!$Q$5:$Q$185,"PENDIENTE") -> 13 | H26: =COUNTIFS(SEGUIMIENTO_PROYECTOS!$A$5:$A$185,DASHBOARD_KPIs!$E$3,SEGUIMIENTO_PROYECTOS!$Q$5:$Q$185,"NO APLICA") -> 105 | I26: =IFERROR((COUNTIFS(SEGUIMIENTO_PROYECTOS!$A$5:$A$185,DASHBOARD_KPIs!$E$3,SEGUIMIENTO_PROYECTOS!$Q$5:$Q$185,"OK")+COUNTIFS(SEGUIMIENTO_PROYECTOS!$A$5:$A$185,DASHBOARD_KPIs!$E$3,SEGUIMIENTO_PROYECTOS!$Q$5:$Q$185,"OK (falta firma)")*0.75+COUNTIFS(SEGUIMIENTO_PROYECTOS!$A$5:$A$185,DASHBOARD_KPIs!$E$3,SEGUIMIENTO_PROYECTOS!$Q$5:$Q$185,"EN PROCESO")*0.5)/(COUNTIFS(SEGUIMIENTO_PROYECTOS!$A$5:$A$185,DASHBOARD_KPIs!$E$3)-COUNTIFS(SEGUIMIENTO_PROYECTOS!$A$5:$A$185,DASHBOARD_KPIs!$E$3,SEGUIMIENTO_PROYECTOS!$Q$5:$Q$185,"NO APLICA")-COUNTIFS(SEGUIMIENTO_PROYECTOS!$A$5:$A$185,DASHBOARD_KPIs!$E$3,SEGUIMIENTO_PROYECTOS!$Q$5:$Q$185,"-")-COUNTIFS(SEGUIMIENTO_PROYECTOS!$A$5:$A$185,DASHBOARD_KPIs!$E$3,SEGUIMIENTO_PROYECTOS!$Q$5:$Q$185,"")),"") -> 0.796875 | J26: =IFERROR(IF(I26>=0.9,"CONFORME",IF(I26>=0.5,"ALERTA","CRITICO")),"S/D") -> ALERTA
B28: 👤 CUMPLIMIENTO POR RESPONSABLE — JEFE DE PROYECTO
B29: RESPONSABLE | C29: ACTIVOS | D29: CONFORME | E29: ALERTA | F29: CRITICO | G29: CERRADOS | H29: STAND BY | I29: % SIG PROM.
B30: A. Ferrer | C30: =COUNTIFS(SEGUIMIENTO_PROYECTOS!$A$5:$A$185,DASHBOARD_KPIs!$E$3,SEGUIMIENTO_PROYECTOS!$H$5:$H$185,"A. Ferrer")-COUNTIFS(SEGUIMIENTO_PROYECTOS!$A$5:$A$185,DASHBOARD_KPIs!$E$3,SEGUIMIENTO_PROYECTOS!$H$5:$H$185,"A. Ferrer",SEGUIMIENTO_PROYECTOS!$F$5:$F$185,"CERRADO")-COUNTIFS(SEGUIMIENTO_PROYECTOS!$A$5:$A$185,DASHBOARD_KPIs!$E$3,SEGUIMIENTO_PROYECTOS!$H$5:$H$185,"A. Ferrer",SEGUIMIENTO_PROYECTOS!$F$5:$F$185,"CANCELADO")-COUNTIFS(SEGUIMIENTO_PROYECTOS!$A$5:$A$185,DASHBOARD_KPIs!$E$3,SEGUIMIENTO_PROYECTOS!$H$5:$H$185,"A. Ferrer",SEGUIMIENTO_PROYECTOS!$F$5:$F$185,"DESCARTADO") -> 6 | D30: =COUNTIFS(SEGUIMIENTO_PROYECTOS!$A$5:$A$185,DASHBOARD_KPIs!$E$3,SEGUIMIENTO_PROYECTOS!$H$5:$H$185,"A. Ferrer",SEGUIMIENTO_PROYECTOS!$W$5:$W$185,"CONFORME") -> 0 | E30: =COUNTIFS(SEGUIMIENTO_PROYECTOS!$A$5:$A$185,DASHBOARD_KPIs!$E$3,SEGUIMIENTO_PROYECTOS!$H$5:$H$185,"A. Ferrer",SEGUIMIENTO_PROYECTOS!$W$5:$W$185,"ALERTA") -> 5 | F30: =COUNTIFS(SEGUIMIENTO_PROYECTOS!$A$5:$A$185,DASHBOARD_KPIs!$E$3,SEGUIMIENTO_PROYECTOS!$H$5:$H$185,"A. Ferrer",SEGUIMIENTO_PROYECTOS!$W$5:$W$185,"CRITICO") -> 7 | G30: =COUNTIFS(SEGUIMIENTO_PROYECTOS!$A$5:$A$185,DASHBOARD_KPIs!$E$3,SEGUIMIENTO_PROYECTOS!$H$5:$H$185,"A. Ferrer",SEGUIMIENTO_PROYECTOS!$F$5:$F$185,"CERRADO") -> 6 | H30: =COUNTIFS(SEGUIMIENTO_PROYECTOS!$A$5:$A$185,DASHBOARD_KPIs!$E$3,SEGUIMIENTO_PROYECTOS!$H$5:$H$185,"A. Ferrer",SEGUIMIENTO_PROYECTOS!$W$5:$W$185,"STAND BY") -> 0 | I30: =IFERROR(SUMIFS(SEGUIMIENTO_PROYECTOS!$Y$5:$Y$185,SEGUIMIENTO_PROYECTOS!$A$5:$A$185,DASHBOARD_KPIs!$E$3,SEGUIMIENTO_PROYECTOS!$H$5:$H$185,"A. Ferrer")/SUMIFS(SEGUIMIENTO_PROYECTOS!$X$5:$X$185,SEGUIMIENTO_PROYECTOS!$A$5:$A$185,DASHBOARD_KPIs!$E$3,SEGUIMIENTO_PROYECTOS!$H$5:$H$185,"A. Ferrer"),"—") -> 0.40769231
B31: B. López | C31: =COUNTIFS(SEGUIMIENTO_PROYECTOS!$A$5:$A$185,DASHBOARD_KPIs!$E$3,SEGUIMIENTO_PROYECTOS!$H$5:$H$185,"B. López")-COUNTIFS(SEGUIMIENTO_PROYECTOS!$A$5:$A$185,DASHBOARD_KPIs!$E$3,SEGUIMIENTO_PROYECTOS!$H$5:$H$185,"B. López",SEGUIMIENTO_PROYECTOS!$F$5:$F$185,"CERRADO")-COUNTIFS(SEGUIMIENTO_PROYECTOS!$A$5:$A$185,DASHBOARD_KPIs!$E$3,SEGUIMIENTO_PROYECTOS!$H$5:$H$185,"B. López",SEGUIMIENTO_PROYECTOS!$F$5:$F$185,"CANCELADO")-COUNTIFS(SEGUIMIENTO_PROYECTOS!$A$5:$A$185,DASHBOARD_KPIs!$E$3,SEGUIMIENTO_PROYECTOS!$H$5:$H$185,"B. López",SEGUIMIENTO_PROYECTOS!$F$5:$F$185,"DESCARTADO") -> 13 | D31: =COUNTIFS(SEGUIMIENTO_PROYECTOS!$A$5:$A$185,DASHBOARD_KPIs!$E$3,SEGUIMIENTO_PROYECTOS!$H$5:$H$185,"B. López",SEGUIMIENTO_PROYECTOS!$W$5:$W$185,"CONFORME") -> 3 | E31: =COUNTIFS(SEGUIMIENTO_PROYECTOS!$A$5:$A$185,DASHBOARD_KPIs!$E$3,SEGUIMIENTO_PROYECTOS!$H$5:$H$185,"B. López",SEGUIMIENTO_PROYECTOS!$W$5:$W$185,"ALERTA") -> 13 | F31: =COUNTIFS(SEGUIMIENTO_PROYECTOS!$A$5:$A$185,DASHBOARD_KPIs!$E$3,SEGUIMIENTO_PROYECTOS!$H$5:$H$185,"B. López",SEGUIMIENTO_PROYECTOS!$W$5:$W$185,"CRITICO") -> 11 | G31: =COUNTIFS(SEGUIMIENTO_PROYECTOS!$A$5:$A$185,DASHBOARD_KPIs!$E$3,SEGUIMIENTO_PROYECTOS!$H$5:$H$185,"B. López",SEGUIMIENTO_PROYECTOS!$F$5:$F$185,"CERRADO") -> 16 | H31: =COUNTIFS(SEGUIMIENTO_PROYECTOS!$A$5:$A$185,DASHBOARD_KPIs!$E$3,SEGUIMIENTO_PROYECTOS!$H$5:$H$185,"B. López",SEGUIMIENTO_PROYECTOS!$W$5:$W$185,"STAND BY") -> 0 | I31: =IFERROR(SUMIFS(SEGUIMIENTO_PROYECTOS!$Y$5:$Y$185,SEGUIMIENTO_PROYECTOS!$A$5:$A$185,DASHBOARD_KPIs!$E$3,SEGUIMIENTO_PROYECTOS!$H$5:$H$185,"B. López")/SUMIFS(SEGUIMIENTO_PROYECTOS!$X$5:$X$185,SEGUIMIENTO_PROYECTOS!$A$5:$A$185,DASHBOARD_KPIs!$E$3,SEGUIMIENTO_PROYECTOS!$H$5:$H$185,"B. López"),"—") -> 0.48275862
B32: C. Castillo | C32: =COUNTIFS(SEGUIMIENTO_PROYECTOS!$A$5:$A$185,DASHBOARD_KPIs!$E$3,SEGUIMIENTO_PROYECTOS!$H$5:$H$185,"C. Castillo")-COUNTIFS(SEGUIMIENTO_PROYECTOS!$A$5:$A$185,DASHBOARD_KPIs!$E$3,SEGUIMIENTO_PROYECTOS!$H$5:$H$185,"C. Castillo",SEGUIMIENTO_PROYECTOS!$F$5:$F$185,"CERRADO")-COUNTIFS(SEGUIMIENTO_PROYECTOS!$A$5:$A$185,DASHBOARD_KPIs!$E$3,SEGUIMIENTO_PROYECTOS!$H$5:$H$185,"C. Castillo",SEGUIMIENTO_PROYECTOS!$F$5:$F$185,"CANCELADO")-COUNTIFS(SEGUIMIENTO_PROYECTOS!$A$5:$A$185,DASHBOARD_KPIs!$E$3,SEGUIMIENTO_PROYECTOS!$H$5:$H$185,"C. Castillo",SEGUIMIENTO_PROYECTOS!$F$5:$F$185,"DESCARTADO") -> 1 | D32: =COUNTIFS(SEGUIMIENTO_PROYECTOS!$A$5:$A$185,DASHBOARD_KPIs!$E$3,SEGUIMIENTO_PROYECTOS!$H$5:$H$185,"C. Castillo",SEGUIMIENTO_PROYECTOS!$W$5:$W$185,"CONFORME") -> 10 | E32: =COUNTIFS(SEGUIMIENTO_PROYECTOS!$A$5:$A$185,DASHBOARD_KPIs!$E$3,SEGUIMIENTO_PROYECTOS!$H$5:$H$185,"C. Castillo",SEGUIMIENTO_PROYECTOS!$W$5:$W$185,"ALERTA") -> 1 | F32: =COUNTIFS(SEGUIMIENTO_PROYECTOS!$A$5:$A$185,DASHBOARD_KPIs!$E$3,SEGUIMIENTO_PROYECTOS!$H$5:$H$185,"C. Castillo",SEGUIMIENTO_PROYECTOS!$W$5:$W$185,"CRITICO") -> 0 | G32: =COUNTIFS(SEGUIMIENTO_PROYECTOS!$A$5:$A$185,DASHBOARD_KPIs!$E$3,SEGUIMIENTO_PROYECTOS!$H$5:$H$185,"C. Castillo",SEGUIMIENTO_PROYECTOS!$F$5:$F$185,"CERRADO") -> 11 | H32: =COUNTIFS(SEGUIMIENTO_PROYECTOS!$A$5:$A$185,DASHBOARD_KPIs!$E$3,SEGUIMIENTO_PROYECTOS!$H$5:$H$185,"C. Castillo",SEGUIMIENTO_PROYECTOS!$W$5:$W$185,"STAND BY") -> 0 | I32: =IFERROR(SUMIFS(SEGUIMIENTO_PROYECTOS!$Y$5:$Y$185,SEGUIMIENTO_PROYECTOS!$A$5:$A$185,DASHBOARD_KPIs!$E$3,SEGUIMIENTO_PROYECTOS!$H$5:$H$185,"C. Castillo")/SUMIFS(SEGUIMIENTO_PROYECTOS!$X$5:$X$185,SEGUIMIENTO_PROYECTOS!$A$5:$A$185,DASHBOARD_KPIs!$E$3,SEGUIMIENTO_PROYECTOS!$H$5:$H$185,"C. Castillo"),"—") -> 0.98333333
B33: C. Castillo / Michael Gómez | C33: =COUNTIFS(SEGUIMIENTO_PROYECTOS!$A$5:$A$185,DASHBOARD_KPIs!$E$3,SEGUIMIENTO_PROYECTOS!$H$5:$H$185,"C. Castillo / Michael Gómez")-COUNTIFS(SEGUIMIENTO_PROYECTOS!$A$5:$A$185,DASHBOARD_KPIs!$E$3,SEGUIMIENTO_PROYECTOS!$H$5:$H$185,"C. Castillo / Michael Gómez",SEGUIMIENTO_PROYECTOS!$F$5:$F$185,"CERRADO")-COUNTIFS(SEGUIMIENTO_PROYECTOS!$A$5:$A$185,DASHBOARD_KPIs!$E$3,SEGUIMIENTO_PROYECTOS!$H$5:$H$185,"C. Castillo / Michael Gómez",SEGUIMIENTO_PROYECTOS!$F$5:$F$185,"CANCELADO")-COUNTIFS(SEGUIMIENTO_PROYECTOS!$A$5:$A$185,DASHBOARD_KPIs!$E$3,SEGUIMIENTO_PROYECTOS!$H$5:$H$185,"C. Castillo / Michael Gómez",SEGUIMIENTO_PROYECTOS!$F$5:$F$185,"DESCARTADO") -> 0 | D33: =COUNTIFS(SEGUIMIENTO_PROYECTOS!$A$5:$A$185,DASHBOARD_KPIs!$E$3,SEGUIMIENTO_PROYECTOS!$H$5:$H$185,"C. Castillo / Michael Gómez",SEGUIMIENTO_PROYECTOS!$W$5:$W$185,"CONFORME") -> 3 | E33: =COUNTIFS(SEGUIMIENTO_PROYECTOS!$A$5:$A$185,DASHBOARD_KPIs!$E$3,SEGUIMIENTO_PROYECTOS!$H$5:$H$185,"C. Castillo / Michael Gómez",SEGUIMIENTO_PROYECTOS!$W$5:$W$185,"ALERTA") -> 3 | F33: =COUNTIFS(SEGUIMIENTO_PROYECTOS!$A$5:$A$185,DASHBOARD_KPIs!$E$3,SEGUIMIENTO_PROYECTOS!$H$5:$H$185,"C. Castillo / Michael Gómez",SEGUIMIENTO_PROYECTOS!$W$5:$W$185,"CRITICO") -> 0 | G33: =COUNTIFS(SEGUIMIENTO_PROYECTOS!$A$5:$A$185,DASHBOARD_KPIs!$E$3,SEGUIMIENTO_PROYECTOS!$H$5:$H$185,"C. Castillo / Michael Gómez",SEGUIMIENTO_PROYECTOS!$F$5:$F$185,"CERRADO") -> 6 | H33: =COUNTIFS(SEGUIMIENTO_PROYECTOS!$A$5:$A$185,DASHBOARD_KPIs!$E$3,SEGUIMIENTO_PROYECTOS!$H$5:$H$185,"C. Castillo / Michael Gómez",SEGUIMIENTO_PROYECTOS!$W$5:$W$185,"STAND BY") -> 0 | I33: =IFERROR(SUMIFS(SEGUIMIENTO_PROYECTOS!$Y$5:$Y$185,SEGUIMIENTO_PROYECTOS!$A$5:$A$185,DASHBOARD_KPIs!$E$3,SEGUIMIENTO_PROYECTOS!$H$5:$H$185,"C. Castillo / Michael Gómez")/SUMIFS(SEGUIMIENTO_PROYECTOS!$X$5:$X$185,SEGUIMIENTO_PROYECTOS!$A$5:$A$185,DASHBOARD_KPIs!$E$3,SEGUIMIENTO_PROYECTOS!$H$5:$H$185,"C. Castillo / Michael Gómez"),"—") -> 0.83333333
B34: C. Valdizán | C34: =COUNTIFS(SEGUIMIENTO_PROYECTOS!$A$5:$A$185,DASHBOARD_KPIs!$E$3,SEGUIMIENTO_PROYECTOS!$H$5:$H$185,"C. Valdizán")-COUNTIFS(SEGUIMIENTO_PROYECTOS!$A$5:$A$185,DASHBOARD_KPIs!$E$3,SEGUIMIENTO_PROYECTOS!$H$5:$H$185,"C. Valdizán",SEGUIMIENTO_PROYECTOS!$F$5:$F$185,"CERRADO")-COUNTIFS(SEGUIMIENTO_PROYECTOS!$A$5:$A$185,DASHBOARD_KPIs!$E$3,SEGUIMIENTO_PROYECTOS!$H$5:$H$185,"C. Valdizán",SEGUIMIENTO_PROYECTOS!$F$5:$F$185,"CANCELADO")-COUNTIFS(SEGUIMIENTO_PROYECTOS!$A$5:$A$185,DASHBOARD_KPIs!$E$3,SEGUIMIENTO_PROYECTOS!$H$5:$H$185,"C. Valdizán",SEGUIMIENTO_PROYECTOS!$F$5:$F$185,"DESCARTADO") -> 0 | D34: =COUNTIFS(SEGUIMIENTO_PROYECTOS!$A$5:$A$185,DASHBOARD_KPIs!$E$3,SEGUIMIENTO_PROYECTOS!$H$5:$H$185,"C. Valdizán",SEGUIMIENTO_PROYECTOS!$W$5:$W$185,"CONFORME") -> 1 | E34: =COUNTIFS(SEGUIMIENTO_PROYECTOS!$A$5:$A$185,DASHBOARD_KPIs!$E$3,SEGUIMIENTO_PROYECTOS!$H$5:$H$185,"C. Valdizán",SEGUIMIENTO_PROYECTOS!$W$5:$W$185,"ALERTA") -> 0 | F34: =COUNTIFS(SEGUIMIENTO_PROYECTOS!$A$5:$A$185,DASHBOARD_KPIs!$E$3,SEGUIMIENTO_PROYECTOS!$H$5:$H$185,"C. Valdizán",SEGUIMIENTO_PROYECTOS!$W$5:$W$185,"CRITICO") -> 1 | G34: =COUNTIFS(SEGUIMIENTO_PROYECTOS!$A$5:$A$185,DASHBOARD_KPIs!$E$3,SEGUIMIENTO_PROYECTOS!$H$5:$H$185,"C. Valdizán",SEGUIMIENTO_PROYECTOS!$F$5:$F$185,"CERRADO") -> 2 | H34: =COUNTIFS(SEGUIMIENTO_PROYECTOS!$A$5:$A$185,DASHBOARD_KPIs!$E$3,SEGUIMIENTO_PROYECTOS!$H$5:$H$185,"C. Valdizán",SEGUIMIENTO_PROYECTOS!$W$5:$W$185,"STAND BY") -> 0 | I34: =IFERROR(SUMIFS(SEGUIMIENTO_PROYECTOS!$Y$5:$Y$185,SEGUIMIENTO_PROYECTOS!$A$5:$A$185,DASHBOARD_KPIs!$E$3,SEGUIMIENTO_PROYECTOS!$H$5:$H$185,"C. Valdizán")/SUMIFS(SEGUIMIENTO_PROYECTOS!$X$5:$X$185,SEGUIMIENTO_PROYECTOS!$A$5:$A$185,DASHBOARD_KPIs!$E$3,SEGUIMIENTO_PROYECTOS!$H$5:$H$185,"C. Valdizán"),"—") -> 0.71428571
B35: F. Choque | C35: =COUNTIFS(SEGUIMIENTO_PROYECTOS!$A$5:$A$185,DASHBOARD_KPIs!$E$3,SEGUIMIENTO_PROYECTOS!$H$5:$H$185,"F. Choque")-COUNTIFS(SEGUIMIENTO_PROYECTOS!$A$5:$A$185,DASHBOARD_KPIs!$E$3,SEGUIMIENTO_PROYECTOS!$H$5:$H$185,"F. Choque",SEGUIMIENTO_PROYECTOS!$F$5:$F$185,"CERRADO")-COUNTIFS(SEGUIMIENTO_PROYECTOS!$A$5:$A$185,DASHBOARD_KPIs!$E$3,SEGUIMIENTO_PROYECTOS!$H$5:$H$185,"F. Choque",SEGUIMIENTO_PROYECTOS!$F$5:$F$185,"CANCELADO")-COUNTIFS(SEGUIMIENTO_PROYECTOS!$A$5:$A$185,DASHBOARD_KPIs!$E$3,SEGUIMIENTO_PROYECTOS!$H$5:$H$185,"F. Choque",SEGUIMIENTO_PROYECTOS!$F$5:$F$185,"DESCARTADO") -> 13 | D35: =COUNTIFS(SEGUIMIENTO_PROYECTOS!$A$5:$A$185,DASHBOARD_KPIs!$E$3,SEGUIMIENTO_PROYECTOS!$H$5:$H$185,"F. Choque",SEGUIMIENTO_PROYECTOS!$W$5:$W$185,"CONFORME") -> 7 | E35: =COUNTIFS(SEGUIMIENTO_PROYECTOS!$A$5:$A$185,DASHBOARD_KPIs!$E$3,SEGUIMIENTO_PROYECTOS!$H$5:$H$185,"F. Choque",SEGUIMIENTO_PROYECTOS!$W$5:$W$185,"ALERTA") -> 28 | F35: =COUNTIFS(SEGUIMIENTO_PROYECTOS!$A$5:$A$185,DASHBOARD_KPIs!$E$3,SEGUIMIENTO_PROYECTOS!$H$5:$H$185,"F. Choque",SEGUIMIENTO_PROYECTOS!$W$5:$W$185,"CRITICO") -> 13 | G35: =COUNTIFS(SEGUIMIENTO_PROYECTOS!$A$5:$A$185,DASHBOARD_KPIs!$E$3,SEGUIMIENTO_PROYECTOS!$H$5:$H$185,"F. Choque",SEGUIMIENTO_PROYECTOS!$F$5:$F$185,"CERRADO") -> 35 | H35: =COUNTIFS(SEGUIMIENTO_PROYECTOS!$A$5:$A$185,DASHBOARD_KPIs!$E$3,SEGUIMIENTO_PROYECTOS!$H$5:$H$185,"F. Choque",SEGUIMIENTO_PROYECTOS!$W$5:$W$185,"STAND BY") -> 0 | I35: =IFERROR(SUMIFS(SEGUIMIENTO_PROYECTOS!$Y$5:$Y$185,SEGUIMIENTO_PROYECTOS!$A$5:$A$185,DASHBOARD_KPIs!$E$3,SEGUIMIENTO_PROYECTOS!$H$5:$H$185,"F. Choque")/SUMIFS(SEGUIMIENTO_PROYECTOS!$X$5:$X$185,SEGUIMIENTO_PROYECTOS!$A$5:$A$185,DASHBOARD_KPIs!$E$3,SEGUIMIENTO_PROYECTOS!$H$5:$H$185,"F. Choque"),"—") -> 0.58809524
B36: F. Corvera | C36: =COUNTIFS(SEGUIMIENTO_PROYECTOS!$A$5:$A$185,DASHBOARD_KPIs!$E$3,SEGUIMIENTO_PROYECTOS!$H$5:$H$185,"F. Corvera")-COUNTIFS(SEGUIMIENTO_PROYECTOS!$A$5:$A$185,DASHBOARD_KPIs!$E$3,SEGUIMIENTO_PROYECTOS!$H$5:$H$185,"F. Corvera",SEGUIMIENTO_PROYECTOS!$F$5:$F$185,"CERRADO")-COUNTIFS(SEGUIMIENTO_PROYECTOS!$A$5:$A$185,DASHBOARD_KPIs!$E$3,SEGUIMIENTO_PROYECTOS!$H$5:$H$185,"F. Corvera",SEGUIMIENTO_PROYECTOS!$F$5:$F$185,"CANCELADO")-COUNTIFS(SEGUIMIENTO_PROYECTOS!$A$5:$A$185,DASHBOARD_KPIs!$E$3,SEGUIMIENTO_PROYECTOS!$H$5:$H$185,"F. Corvera",SEGUIMIENTO_PROYECTOS!$F$5:$F$185,"DESCARTADO") -> 0 | D36: =COUNTIFS(SEGUIMIENTO_PROYECTOS!$A$5:$A$185,DASHBOARD_KPIs!$E$3,SEGUIMIENTO_PROYECTOS!$H$5:$H$185,"F. Corvera",SEGUIMIENTO_PROYECTOS!$W$5:$W$185,"CONFORME") -> 0 | E36: =COUNTIFS(SEGUIMIENTO_PROYECTOS!$A$5:$A$185,DASHBOARD_KPIs!$E$3,SEGUIMIENTO_PROYECTOS!$H$5:$H$185,"F. Corvera",SEGUIMIENTO_PROYECTOS!$W$5:$W$185,"ALERTA") -> 1 | F36: =COUNTIFS(SEGUIMIENTO_PROYECTOS!$A$5:$A$185,DASHBOARD_KPIs!$E$3,SEGUIMIENTO_PROYECTOS!$H$5:$H$185,"F. Corvera",SEGUIMIENTO_PROYECTOS!$W$5:$W$185,"CRITICO") -> 1 | G36: =COUNTIFS(SEGUIMIENTO_PROYECTOS!$A$5:$A$185,DASHBOARD_KPIs!$E$3,SEGUIMIENTO_PROYECTOS!$H$5:$H$185,"F. Corvera",SEGUIMIENTO_PROYECTOS!$F$5:$F$185,"CERRADO") -> 2 | H36: =COUNTIFS(SEGUIMIENTO_PROYECTOS!$A$5:$A$185,DASHBOARD_KPIs!$E$3,SEGUIMIENTO_PROYECTOS!$H$5:$H$185,"F. Corvera",SEGUIMIENTO_PROYECTOS!$W$5:$W$185,"STAND BY") -> 0 | I36: =IFERROR(SUMIFS(SEGUIMIENTO_PROYECTOS!$Y$5:$Y$185,SEGUIMIENTO_PROYECTOS!$A$5:$A$185,DASHBOARD_KPIs!$E$3,SEGUIMIENTO_PROYECTOS!$H$5:$H$185,"F. Corvera")/SUMIFS(SEGUIMIENTO_PROYECTOS!$X$5:$X$185,SEGUIMIENTO_PROYECTOS!$A$5:$A$185,DASHBOARD_KPIs!$E$3,SEGUIMIENTO_PROYECTOS!$H$5:$H$185,"F. Corvera"),"—") -> 0.36363636
